Workbook

Sheet Stammdaten - Schwimmer
A1: Sponsorenschwimmen
A2: Schwimmer (bis zu 100 Schwimmer vorgesehen; Dunkelblau =Testdaten und No-Shows)
A3: Nummer | B3: Name | C3: Vormname | D3: Geburtstag | E3: Mannschaft | F3: Anzahl Bahnen | G3: Sponsor Nr. | H3: Spendehöhe pro Bahn | I3: Max Betrag | J3: Spenden- Ergebnis | K3: Sponsor Nr. | L3: Spendehöhe pro Bahn | M3: Max Betrag | N3: Spenden- Ergebnis | O3: Sponsor Nr. | P3: Spendehöhe pro Bahn | Q3: Max Betrag | R3: Spenden Ergebnis | S3: Sponsor Nr. | T3: Spendehöhe pro Bahn | U3: Max Betrag | V3: Spenden Ergebnis | W3: Sponsor Nr. | X3: Spendehöhe pro Bahn | Y3: Max Betrag | Z3: Spenden Ergebnis
A4: 2 | V4: =IF(AND(F4*T4>U4,U4>0),U4, F4*T4) -> 0 | Z4: =IF(AND(F4*X4>Y4,Y4>0),Y4, F4*X4) -> 0
A5: 3 | V5: =IF(AND(F5*T5>U5,U5>0),U5, F5*T5) -> 0 | Z5: =IF(AND(F5*X5>Y5,Y5>0),Y5, F5*X5) -> 0
A6: 4 | V6: =IF(AND(F6*T6>U6,U6>0),U6, F6*T6) -> 0 | Z6: =IF(AND(F6*X6>Y6,Y6>0),Y6, F6*X6) -> 0
A7: 5 | B7: Rink | C7: Wiebke | D7: 42566 | E7: 503.505 | F7: 76 | G7: 1003 | H7: 0.5 | J7: =IF(AND(F7*H7>I7,I7>0),I7, F7*H7) -> 38 | K7: 1005 | L7: 0.5 | N7: =IF(AND(F7*L7>M7,M7>0),M7, F7*L7) -> 38 | O7: 1110 | P7: 0.25 | R7: =IF(AND(F7*P7>Q7,Q7>0),Q7, F7*P7) -> 19 | S7: 1111 | T7: 1 | V7: =IF(AND(F7*T7>U7,U7>0),U7, F7*T7) -> 76 | Z7: =IF(AND(F7*X7>Y7,Y7>0),Y7, F7*X7) -> 0
A8: 6 | B8: Künsemüller | C8: Viktoria | D8: 40021 | E8: 503 | F8: 58 | G8: 1003 | H8: 0.5 | J8: =IF(AND(F8*H8>I8,I8>0),I8, F8*H8) -> 29 | N8: =IF(AND(F8*L8>M8,M8>0),M8, F8*L8) -> 0 | R8: =IF(AND(F8*P8>Q8,Q8>0),Q8, F8*P8) -> 0 | V8: =IF(AND(F8*T8>U8,U8>0),U8, F8*T8) -> 0 | Z8: =IF(AND(F8*X8>Y8,Y8>0),Y8, F8*X8) -> 0
A9: 7 | V9: =IF(AND(F9*T9>U9,U9>0),U9, F9*T9) -> 0 | Z9: =IF(AND(F9*X9>Y9,Y9>0),Y9, F9*X9) -> 0
A10: 8 | V10: =IF(AND(F10*T10>U10,U10>0),U10, F10*T10) -> 0 | Z10: =IF(AND(F10*X10>Y10,Y10>0),Y10, F10*X10) -> 0
A11: 9 | B11: Künsemüller | C11: Jessika | D11: 40654 | E11: 503 | F11: 70 | G11: 1003 | H11: 0.5 | J11: =IF(AND(F11*H11>I11,I11>0),I11, F11*H11) -> 35 | N11: =IF(AND(F11*L11>M11,M11>0),M11, F11*L11) -> 0 | R11: =IF(AND(F11*P11>Q11,Q11>0),Q11, F11*P11) -> 0 | V11: =IF(AND(F11*T11>U11,U11>0),U11, F11*T11) -> 0 | Z11: =IF(AND(F4*X11>Y11,Y11>0),Y11, F4*X11) -> 0
A12: 10 | V12: =IF(AND(F12*T12>U12,U12>0),U12, F12*T12) -> 0 | Z12: =IF(AND(F12*X12>Y12,Y12>0),Y12, F12*X12) -> 0
A13: 11 | V13: =IF(AND(F13*T13>U13,U13>0),U13, F13*T13) -> 0 | Z13: =IF(AND(F13*X13>Y13,Y13>0),Y13, F13*X13) -> 0
A14: 12 | V14: =IF(AND(F14*T14>U14,U14>0),U14, F14*T14) -> 0 | Z14: =IF(AND(F14*X14>Y14,Y14>0),Y14, F14*X14) -> 0
A15: 13 | V15: =IF(AND(F15*T15>U15,U15>0),U15, F15*T15) -> 0 | Z15: =IF(AND(F15*X15>Y15,Y15>0),Y15, F15*X15) -> 0
A16: 14 | V16: =IF(AND(F16*T16>U16,U16>0),U16, F16*T16) -> 0 | Z16: =IF(AND(F16*X16>Y16,Y16>0),Y16, F16*X16) -> 0
A17: 15 | V17: =IF(AND(F17*T17>U17,U17>0),U17, F17*T17) -> 0 | Z17: =IF(AND(F17*X17>Y17,Y17>0),Y17, F17*X17) -> 0
A18: 16 | V18: =IF(AND(F18*T18>U18,U18>0),U18, F18*T18) -> 0 | Z18: =IF(AND(F18*X18>Y18,Y18>0),Y18, F18*X18) -> 0
A19: 17 | V19: =IF(AND(F19*T19>U19,U19>0),U19, F19*T19) -> 0 | Z19: =IF(AND(F19*X19>Y19,Y19>0),Y19, F19*X19) -> 0
A20: 18 | V20: =IF(AND(F20*T20>U20,U20>0),U20, F20*T20) -> 0 | Z20: =IF(AND(F20*X20>Y20,Y20>0),Y20, F20*X20) -> 0
A21: 19 | V21: =IF(AND(F21*T21>U21,U21>0),U21, F21*T21) -> 0 | Z21: =IF(AND(F21*X21>Y21,Y21>0),Y21, F21*X21) -> 0
A22: 20 | V22: =IF(AND(F22*T22>U22,U22>0),U22, F22*T22) -> 0 | Z22: =IF(AND(F22*X22>Y22,Y22>0),Y22, F22*X22) -> 0
A23: 21 | V23: =IF(AND(F23*T23>U23,U23>0),U23, F23*T23) -> 0 | Z23: =IF(AND(F23*X23>Y23,Y23>0),Y23, F23*X23) -> 0
... A27: 25 | V27: =IF(AND(F27*T27>U27,U27>0),U27, F27*T27) -> 0 | Z27: =IF(AND(F27*X27>Y27,Y27>0),Y27, F27*X27) -> 0
A28: 26 | B28: Bauer | C28: Tim | D28: 35823 | E28: 503 | F28: 58 | G28: 1003 | H28: 0.5 | J28: =IF(AND(F28*H28>I28,I28>0),I28, F28*H28) -> 29 | N28: =IF(AND(F28*L28>M28,M28>0),M28, F28*L28) -> 0 | R28: =IF(AND(F28*P28>Q28,Q28>0),Q28, F28*P28) -> 0 | V28: =IF(AND(F28*T28>U28,U28>0),U28, F28*T28) -> 0 | Z28: =IF(AND(F28*X28>Y28,Y28>0),Y28, F28*X28) -> 0
A29: 27 | N29: =IF(AND(F29*L29>M29,M29>0),M29, F29*L29) -> 0 | R29: =IF(AND(F29*P29>Q29,Q29>0),Q29, F29*P29) -> 0 | V29: =IF(AND(F29*T29>U29,U29>0),U29, F29*T29) -> 0 | Z29: =IF(AND(F29*X29>Y29,Y29>0),Y29, F29*X29) -> 0
A30: 28 | N30: =IF(AND(F30*L30>M30,M30>0),M30, F30*L30) -> 0 | R30: =IF(AND(F30*P30>Q30,Q30>0),Q30, F30*P30) -> 0 | V30: =IF(AND(F30*T30>U30,U30>0),U30, F30*T30) -> 0 | Z30: =IF(AND(F30*X30>Y30,Y30>0),Y30, F30*X30) -> 0
A31: 29 | N31: =IF(AND(F31*L31>M31,M31>0),M31, F31*L31) -> 0 | R31: =IF(AND(F31*P31>Q31,Q31>0),Q31, F31*P31) -> 0 | V31: =IF(AND(F31*T31>U31,U31>0),U31, F31*T31) -> 0 | Z31: =IF(AND(F31*X31>Y31,Y31>0),Y31, F31*X31) -> 0
A32: 30 | B32: Kombacher | C32: Mia | D32: 43635 | E32: 502 | F32: 40 | G32: 1002 | H32: 0.5 | J32: =IF(AND(F32*H32>I32,I32>0),I32, F32*H32) -> 20 | K32: 1022 | L32: 0.5 | M32: 50 | N32: =IF(AND(F32*L32>M32,M32>0),M32, F32*L32) -> 20 | O32: 1023 | P32: 0.5 | Q32: 50 | R32: =IF(AND(F32*P32>Q32,Q32>0),Q32, F32*P32) -> 20 | S32: 1024 | T32: 0.5 | U32: 50 | V32: =IF(AND(F32*T32>U32,U32>0),U32, F32*T32) -> 20 | Z32: =IF(AND(F32*X32>Y32,Y32>0),Y32, F32*X32) -> 0
A33: 31 | B33: Kombacher | C33: Anja | D33: 30515 | E33: 502 | F33: 46 | G33: 1002 | H33: 0.5 | J33: =IF(AND(F33*H33>I33,I33>0),I33, F33*H33) -> 23 | K33: 1022 | L33: 0.5 | M33: 50 | N33: =IF(AND(F33*L33>M33,M33>0),M33, F33*L33) -> 23 | O33: 1023 | P33: 0.5 | Q33: 50 | R33: =IF(AND(F33*P33>Q33,Q33>0),Q33, F33*P33) -> 23 | S33: 1024 | T33: 0.5 | U33: 50 | V33: =IF(AND(F33*T33>U33,U33>0),U33, F33*T33) -> 23 | Z33: =IF(AND(F33*X33>Y33,Y33>0),Y33, F33*X33) -> 0
A34: 32 | R34: =IF(AND(F34*P34>Q34,Q34>0),Q34, F34*P34) -> 0 | V34: =IF(AND(F34*T34>U34,U34>0),U34, F34*T34) -> 0 | Z34: =IF(AND(F34*X34>Y34,Y34>0),Y34, F34*X34) -> 0
A35: 33 | B35: Kombacher | C35: Lea | D35: 41712 | E35: 502 | F35: 54 | G35: 1002 | H35: 0.5 | J35: =IF(AND(F35*H35>I35,I35>0),I35, F35*H35) -> 27 | K35: 1022 | L35: 0.5 | M35: 50 | N35: =IF(AND(F35*L35>M35,M35>0),M35, F35*L35) -> 27 | O35: 1023 | P35: 0.5 | Q35: 50 | R35: =IF(AND(F35*P35>Q35,Q35>0),Q35, F35*P35) -> 27 | S35: 1024 | T35: 0.5 | U35: 50 | V35: =IF(AND(F35*T35>U35,U35>0),U35, F35*T35) -> 27 | Z35: =IF(AND(F35*X35>Y35,Y35>0),Y35, F35*X35) -> 0
A36: 34 | V36: =IF(AND(F36*T36>U36,U36>0),U36, F36*T36) -> 0 | Z36: =IF(AND(F36*X36>Y36,Y36>0),Y36, F36*X36) -> 0
A37: 35 | B37: Kombacher | C37: Sara | D37: 42528 | E37: 502 | F37: 84 | G37: 1002 | H37: 0.5 | J37: =IF(AND(F37*H37>I37,I37>0),I37, F37*H37) -> 42 | K37: 1022 | L37: 0.5 | M37: 50 | N37: =IF(AND(F37*L37>M37,M37>0),M37, F37*L37) -> 42 | O37: 1023 | P37: 0.5 | Q37: 50 | R37: =IF(AND(F37*P37>Q37,Q37>0),Q37, F37*P37) -> 42 | S37: 1024 | T37: 0.5 | U37: 50 | V37: =IF(AND(F37*T37>U37,U37>0),U37, F37*T37) -> 42 | Z37: =IF(AND(F37*X37>Y37,Y37>0),Y37, F37*X37) -> 0
A38: 36 | J38: =IF(AND(F38*H38>I38,I38>0),I38, F38*H38) -> 0 | N38: =IF(AND(F38*L38>M38,M38>0),M38, F38*L38) -> 0 | R38: =IF(AND(F38*P38>Q38,Q38>0),Q38, F38*P38) -> 0 | V38: =IF(AND(F38*T38>U38,U38>0),U38, F38*T38) -> 0 | Z38: =IF(AND(F38*X38>Y38,Y38>0),Y38, F38*X38) -> 0
A39: 37 | J39: =IF(AND(F39*H39>I39,I39>0),I39, F39*H39) -> 0 | N39: =IF(AND(F39*L39>M39,M39>0),M39, F39*L39) -> 0 | R39: =IF(AND(F39*P39>Q39,Q39>0),Q39, F39*P39) -> 0 | V39: =IF(AND(F39*T39>U39,U39>0),U39, F39*T39) -> 0 | Z39: =IF(AND(F39*X39>Y39,Y39>0),Y39, F39*X39) -> 0
A40: 38 | J40: =IF(AND(F40*H40>I40,I40>0),I40, F40*H40) -> 0 | N40: =IF(AND(F40*L40>M40,M40>0),M40, F40*L40) -> 0 | R40: =IF(AND(F40*P40>Q40,Q40>0),Q40, F40*P40) -> 0 | V40: =IF(AND(F40*T40>U40,U40>0),U40, F40*T40) -> 0 | Z40: =IF(AND(F40*X40>Y40,Y40>0),Y40, F40*X40) -> 0
A41: 39 | J41: =IF(AND(F41*H41>I41,I41>0),I41, F41*H41) -> 0 | N41: =IF(AND(F41*L41>M41,M41>0),M41, F41*L41) -> 0 | R41: =IF(AND(F41*P41>Q41,Q41>0),Q41, F41*P41) -> 0 | V41: =IF(AND(F41*T41>U41,U41>0),U41, F41*T41) -> 0 | Z41: =IF(AND(F41*X41>Y41,Y41>0),Y41, F41*X41) -> 0
A42: 40 | J42: =IF(AND(F42*H42>I42,I42>0),I42, F42*H42) -> 0 | N42: =IF(AND(F42*L42>M42,M42>0),M42, F42*L42) -> 0 | R42: =IF(AND(F42*P42>Q42,Q42>0),Q42, F42*P42) -> 0 | V42: =IF(AND(F42*T42>U42,U42>0),U42, F42*T42) -> 0 | Z42: =IF(AND(F42*X42>Y42,Y42>0),Y42, F42*X42) -> 0
A43: 41 | J43: =IF(AND(F43*H43>I43,I43>0),I43, F43*H43) -> 0 | N43: =IF(AND(F43*L43>M43,M43>0),M43, F43*L43) -> 0 | R43: =IF(AND(F43*P43>Q43,Q43>0),Q43, F43*P43) -> 0 | V43: =IF(AND(F43*T43>U43,U43>0),U43, F43*T43) -> 0 | Z43: =IF(AND(F43*X43>Y43,Y43>0),Y43, F43*X43) -> 0
...

Sheet Tabelle1
A1: Jungstes Kind | K1: =#REF! -> #REF! | L1: =#REF! -> #REF! | M1: =#REF! -> #REF! | N1: =#REF! -> #REF! | O1: =#REF! -> #REF! | P1: =#REF! -> #REF! | Q1: 50 | R1: =P1*Q1 -> #REF!
A2: ='Stammdaten - Schwimmer'!A3 -> Nummer | B2: ='Stammdaten - Schwimmer'!B3 -> Name | C2: ='Stammdaten - Schwimmer'!C3 -> Vormname | D2: ='Stammdaten - Schwimmer'!D3 -> Geburtstag | E2: ='Stammdaten - Schwimmer'!E3 -> Mannschaft | F2: ='Stammdaten - Schwimmer'!F3 -> Anzahl Bahnen | K2: ='Stammdaten - Schwimmer'!A4 -> 2 | L2: ='stammdaten - schwimmer'!#ref! -> #VALUE! | M2: ='stammdaten - schwimmer'!#ref! -> #VALUE! | N2: ='stammdaten - schwimmer'!#ref! -> #VALUE! | O2: ='stammdaten - schwimmer'!#ref! -> #VALUE! | P2: ='stammdaten - schwimmer'!#ref! -> #VALUE! | Q2: 25 | R2: =P2*Q2 -> #VALUE!
A3: ='Stammdaten - Schwimmer'!A82 -> 80 | B3: ='Stammdaten - Schwimmer'!B82 -> Schönefeld | C3: ='Stammdaten - Schwimmer'!C82 -> Frida Marie | D3: ='Stammdaten - Schwimmer'!D82 -> 43719 | E3: ='Stammdaten - Schwimmer'!E82 -> 0 | F3: ='Stammdaten - Schwimmer'!F82 -> 32 | K3: ='Stammdaten - Schwimmer'!A5 -> 3 | L3: ='Stammdaten - Schwimmer'!B5 -> 0 | M3: ='Stammdaten - Schwimmer'!C5 -> 0 | N3: ='Stammdaten - Schwimmer'!D5 -> 0 | O3: ='Stammdaten - Schwimmer'!E5 -> 0 | P3: ='Stammdaten - Schwimmer'!F5 -> 0 | Q3: 25 | R3: =P3*Q3 -> 0
A4: ='Stammdaten - Schwimmer'!A32 -> 30 | B4: ='Stammdaten - Schwimmer'!B32 -> Kombacher | C4: ='Stammdaten - Schwimmer'!C32 -> Mia | D4: ='Stammdaten - Schwimmer'!D32 -> 43635 | E4: ='Stammdaten - Schwimmer'!E32 -> 502 | F4: ='Stammdaten - Schwimmer'!F32 -> 40 | K4: ='Stammdaten - Schwimmer'!A6 -> 4 | L4: ='Stammdaten - Schwimmer'!B6 -> 0 | M4: ='Stammdaten - Schwimmer'!C6 -> 0 | N4: ='Stammdaten - Schwimmer'!D6 -> 0 | O4: ='Stammdaten - Schwimmer'!E6 -> 0 | P4: ='Stammdaten - Schwimmer'!F6 -> 0 | Q4: 50 | R4: =P4*Q4 -> 0
A5: ='Stammdaten - Schwimmer'!A79 -> 77 | B5: ='Stammdaten - Schwimmer'!B79 -> Rink | C5: ='Stammdaten - Schwimmer'!C79 -> Henrik | D5: ='Stammdaten - Schwimmer'!D79 -> 43484 | E5: ='Stammdaten - Schwimmer'!E79 -> 503.505 | F5: ='Stammdaten - Schwimmer'!F79 -> 48 | K5: ='Stammdaten - Schwimmer'!A7 -> 5 | L5: ='Stammdaten - Schwimmer'!B7 -> Rink | M5: ='Stammdaten - Schwimmer'!C7 -> Wiebke | N5: ='Stammdaten - Schwimmer'!D7 -> 42566 | O5: ='Stammdaten - Schwimmer'!E7 -> 503.505 | P5: ='Stammdaten - Schwimmer'!F7 -> 76 | Q5: 25 | R5: =P5*Q5 -> 1900
A6: ='Stammdaten - Schwimmer'!A7 -> 5 | B6: ='Stammdaten - Schwimmer'!B7 -> Rink | C6: ='Stammdaten - Schwimmer'!C7 -> Wiebke | D6: ='Stammdaten - Schwimmer'!D7 -> 42566 | E6: ='Stammdaten - Schwimmer'!E7 -> 503.505 | F6: ='Stammdaten - Schwimmer'!F7 -> 76 | K6: ='Stammdaten - Schwimmer'!A8 -> 6 | L6: ='Stammdaten - Schwimmer'!B8 -> Künsemüller | M6: ='Stammdaten - Schwimmer'!C8 -> Viktoria | N6: ='Stammdaten - Schwimmer'!D8 -> 40021 | O6: ='Stammdaten - Schwimmer'!E8 -> 503 | P6: ='Stammdaten - Schwimmer'!F8 -> 58 | Q6: 50 | R6: =P6*Q6 -> 2900
A7: ='Stammdaten - Schwimmer'!A36 -> 34 | B7: ='Stammdaten - Schwimmer'!B36 -> 0 | C7: ='Stammdaten - Schwimmer'!C36 -> 0 | D7: ='Stammdaten - Schwimmer'!D36 -> 0 | E7: ='Stammdaten - Schwimmer'!E36 -> 0 | F7: ='Stammdaten - Schwimmer'!F36 -> 0 | K7: ='Stammdaten - Schwimmer'!A9 -> 7 | L7: ='Stammdaten - Schwimmer'!B9 -> 0 | M7: ='Stammdaten - Schwimmer'!C9 -> 0 | N7: ='Stammdaten - Schwimmer'!D9 -> 0 | O7: ='Stammdaten - Schwimmer'!E9 -> 0 | P7: ='Stammdaten - Schwimmer'!F9 -> 0 | Q7: 50 | R7: =P7*Q7 -> 0
A8: ='Stammdaten - Schwimmer'!A37 -> 35 | B8: ='Stammdaten - Schwimmer'!B37 -> Kombacher | C8: ='Stammdaten - Schwimmer'!C37 -> Sara | D8: ='Stammdaten - Schwimmer'!D37 -> 42528 | E8: ='Stammdaten - Schwimmer'!E37 -> 502 | F8: ='Stammdaten - Schwimmer'!F37 -> 84 | K8: ='Stammdaten - Schwimmer'!A10 -> 8 | L8: ='Stammdaten - Schwimmer'!B10 -> 0 | M8: ='Stammdaten - Schwimmer'!C10 -> 0 | N8: ='Stammdaten - Schwimmer'!D10 -> 0 | O8: ='Stammdaten - Schwimmer'!E10 -> 0 | P8: ='Stammdaten - Schwimmer'!F10 -> 0 | Q8: 50 | R8: =P8*Q8 -> 0
A9: ='Stammdaten - Schwimmer'!A75 -> 73 | B9: ='Stammdaten - Schwimmer'!B75 -> Glaser | C9: ='Stammdaten - Schwimmer'!C75 -> Mila | D9: ='Stammdaten - Schwimmer'!D75 -> 42450 | E9: ='Stammdaten - Schwimmer'!E75 -> 0 | F9: ='Stammdaten - Schwimmer'!F75 -> 74 | K9: ='Stammdaten - Schwimmer'!A11 -> 9 | L9: ='Stammdaten - Schwimmer'!B4 -> 0 | M9: ='Stammdaten - Schwimmer'!C4 -> 0 | N9: ='Stammdaten - Schwimmer'!D4 -> 0 | O9: ='Stammdaten - Schwimmer'!E4 -> 0 | P9: ='Stammdaten - Schwimmer'!F4 -> 0 | Q9: 50 | R9: =P9*Q9 -> 0
A10: ='Stammdaten - Schwimmer'!A93 -> 91 | B10: ='Stammdaten - Schwimmer'!B93 -> Veit | C10: ='Stammdaten - Schwimmer'!C93 -> Konstantin | D10: ='Stammdaten - Schwimmer'!D93 -> 42325 | E10: ='Stammdaten - Schwimmer'!E93 -> 0 | F10: ='Stammdaten - Schwimmer'!F93 -> 50 | K10: ='Stammdaten - Schwimmer'!A12 -> 10 | L10: ='Stammdaten - Schwimmer'!B12 -> 0 | M10: ='Stammdaten - Schwimmer'!C12 -> 0 | N10: ='Stammdaten - Schwimmer'!D12 -> 0 | O10: ='Stammdaten - Schwimmer'!E12 -> 0 | P10: ='Stammdaten - Schwimmer'!F12 -> 0 | Q10: 50 | R10: =P10*Q10 -> 0
A11: ='Stammdaten - Schwimmer'!A89 -> 87 | B11: ='Stammdaten - Schwimmer'!B89 -> Tutsch | C11: ='Stammdaten - Schwimmer'!C89 -> Linda | D11: ='Stammdaten - Schwimmer'!D89 -> 41934 | E11: ='Stammdaten - Schwimmer'!E89 -> 505 | F11: ='Stammdaten - Schwimmer'!F89 -> 84 | K11: ='Stammdaten - Schwimmer'!A13 -> 11 | L11: ='Stammdaten - Schwimmer'!B13 -> 0 | M11: ='Stammdaten - Schwimmer'!C13 -> 0 | N11: ='Stammdaten - Schwimmer'!D13 -> 0 | O11: ='Stammdaten - Schwimmer'!E13 -> 0 | P11: ='Stammdaten - Schwimmer'!F13 -> 0 | Q11: 50 | R11: =P11*Q11 -> 0
A12: ='Stammdaten - Schwimmer'!A83 -> 81 | B12: ='Stammdaten - Schwimmer'!B83 -> Mauer | C12: ='Stammdaten - Schwimmer'!C83 -> Mika | D12: ='Stammdaten - Schwimmer'!D83 -> 41857 | E12: ='Stammdaten - Schwimmer'!E83 -> 503 | F12: ='Stammdaten - Schwimmer'!F83 -> 124 | K12: ='Stammdaten - Schwimmer'!A14 -> 12 | L12: ='Stammdaten - Schwimmer'!B14 -> 0 | M12: ='Stammdaten - Schwimmer'!C14 -> 0 | N12: ='Stammdaten - Schwimmer'!D14 -> 0 | O12: ='Stammdaten - Schwimmer'!E14 -> 0 | P12: ='Stammdaten - Schwimmer'!F14 -> 0 | Q12: 50 | R12: =P12*Q12 -> 0
A13: ='Stammdaten - Schwimmer'!A86 -> 84 | B13: ='Stammdaten - Schwimmer'!B86 -> Mauer | C13: ='Stammdaten - Schwimmer'!C86 -> Jana | D13: ='Stammdaten - Schwimmer'!D86 -> 41857 | E13: ='Stammdaten - Schwimmer'!E86 -> 503 | F13: ='Stammdaten - Schwimmer'!F86 -> 42 | K13: ='Stammdaten - Schwimmer'!A15 -> 13 | L13: ='Stammdaten - Schwimmer'!B15 -> 0 | M13: ='Stammdaten - Schwimmer'!C15 -> 0 | N13: ='Stammdaten - Schwimmer'!D15 -> 0 | O13: ='Stammdaten - Schwimmer'!E15 -> 0 | P13: ='Stammdaten - Schwimmer'!F15 -> 0 | Q13: 50 | R13: =P13*Q13 -> 0
A14: ='Stammdaten - Schwimmer'!A34 -> 32 | B14: ='Stammdaten - Schwimmer'!B34 -> 0 | C14: ='Stammdaten - Schwimmer'!C34 -> 0 | D14: ='Stammdaten - Schwimmer'!D34 -> 0 | E14: ='Stammdaten - Schwimmer'!E34 -> 0 | F14: ='Stammdaten - Schwimmer'!F34 -> 0 | K14: ='Stammdaten - Schwimmer'!A16 -> 14 | L14: ='Stammdaten - Schwimmer'!B16 -> 0 | M14: ='Stammdaten - Schwimmer'!C16 -> 0 | N14: ='Stammdaten - Schwimmer'!D16 -> 0 | O14: ='Stammdaten - Schwimmer'!E16 -> 0 | P14: ='Stammdaten - Schwimmer'!F16 -> 0 | Q14: 25 | R14: =P14*Q14 -> 0
A15: ='Stammdaten - Schwimmer'!A35 -> 33 | B15: ='Stammdaten - Schwimmer'!B35 -> Kombacher | C15: ='Stammdaten - Schwimmer'!C35 -> Lea | D15: ='Stammdaten - Schwimmer'!D35 -> 41712 | E15: ='Stammdaten - Schwimmer'!E35 -> 502 | F15: ='Stammdaten - Schwimmer'!F35 -> 54 | K15: ='Stammdaten - Schwimmer'!A17 -> 15 | L15: ='Stammdaten - Schwimmer'!B17 -> 0 | M15: ='Stammdaten - Schwimmer'!C17 -> 0 | N15: ='Stammdaten - Schwimmer'!D17 -> 0 | O15: ='Stammdaten - Schwimmer'!E17 -> 0 | P15: ='Stammdaten - Schwimmer'!F17 -> 0 | Q15: 25 | R15: =P15*Q15 -> 0
A16: ='Stammdaten - Schwimmer'!A78 -> 76 | B16: ='Stammdaten - Schwimmer'!B78 -> Wohlers | C16: ='Stammdaten - Schwimmer'!C78 -> Valentin | D16: ='Stammdaten - Schwimmer'!D78 -> 41498 | E16: ='Stammdaten - Schwimmer'!E78 -> 0 | F16: ='Stammdaten - Schwimmer'!F78 -> 76 | K16: ='Stammdaten - Schwimmer'!A18 -> 16 | L16: ='Stammdaten - Schwimmer'!B18 -> 0 | M16: ='Stammdaten - Schwimmer'!C18 -> 0 | N16: ='Stammdaten - Schwimmer'!D18 -> 0 | O16: ='Stammdaten - Schwimmer'!E18 -> 0 | P16: ='Stammdaten - Schwimmer'!F18 -> 0 | Q16: 50 | R16: =P16*Q16 -> 0
A17: ='Stammdaten - Schwimmer'!A84 -> 82 | B17: ='Stammdaten - Schwimmer'!B84 -> Veit | C17: ='Stammdaten - Schwimmer'!C84 -> Dorothea | D17: ='Stammdaten - Schwimmer'!D84 -> 41475 | E17: ='Stammdaten - Schwimmer'!E84 -> 503 | F17: ='Stammdaten - Schwimmer'!F84 -> 104 | K17: ='Stammdaten - Schwimmer'!A19 -> 17 | L17: ='Stammdaten - Schwimmer'!B19 -> 0 | M17: ='Stammdaten - Schwimmer'!C19 -> 0 | N17: ='Stammdaten - Schwimmer'!D19 -> 0 | O17: ='Stammdaten - Schwimmer'!E19 -> 0 | P17: ='Stammdaten - Schwimmer'!F19 -> 0 | Q17: 25 | R17: =P17*Q17 -> 0
A18: ='Stammdaten - Schwimmer'!A90 -> 88 | B18: ='Stammdaten - Schwimmer'!B90 -> Tutsch | C18: ='Stammdaten - Schwimmer'!C90 -> Daniel | D18: ='Stammdaten - Schwimmer'!D90 -> 41321 | E18: ='Stammdaten - Schwimmer'!E90 -> 505 | F18: ='Stammdaten - Schwimmer'!F90 -> 84 | K18: ='Stammdaten - Schwimmer'!A20 -> 18 | L18: ='Stammdaten - Schwimmer'!B20 -> 0 | M18: ='Stammdaten - Schwimmer'!C20 -> 0 | N18: ='Stammdaten - Schwimmer'!D20 -> 0 | O18: ='Stammdaten - Schwimmer'!E20 -> 0 | P18: ='Stammdaten - Schwimmer'!F20 -> 0 | Q18: 25 | R18: =P18*Q18 -> 0
A19: ='Stammdaten - Schwimmer'!A98 -> 96 | B19: ='Stammdaten - Schwimmer'!B98 -> Schule | C19: ='Stammdaten - Schwimmer'!C98 -> Malik | D19: ='Stammdaten - Schwimmer'!D98 -> 41275 | E19: ='Stammdaten - Schwimmer'!E98 -> 0 | F19: ='Stammdaten - Schwimmer'!F98 -> 36 | K19: ='Stammdaten - Schwimmer'!A21 -> 19 | L19: ='Stammdaten - Schwimmer'!B21 -> 0 | M19: ='Stammdaten - Schwimmer'!C21 -> 0 | N19: ='Stammdaten - Schwimmer'!D21 -> 0 | O19: ='Stammdaten - Schwimmer'!E21 -> 0 | P19: ='Stammdaten - Schwimmer'!F21 -> 0 | Q19: 25 | R19: =P19*Q19 -> 0
A20: ='Stammdaten - Schwimmer'!A11 -> 9 | B20: ='Stammdaten - Schwimmer'!B11 -> Künsemüller | C20: ='Stammdaten - Schwimmer'!C11 -> Jessika | D20: ='Stammdaten - Schwimmer'!D11 -> 40654 | E20: ='Stammdaten - Schwimmer'!E11 -> 503 | F20: ='Stammdaten - Schwimmer'!F11 -> 70 | K20: ='Stammdaten - Schwimmer'!A22 -> 20 | L20: ='Stammdaten - Schwimmer'!B22 -> 0 | M20: ='Stammdaten - Schwimmer'!C22 -> 0 | N20: ='Stammdaten - Schwimmer'!D22 -> 0 | O20: ='Stammdaten - Schwimmer'!E22 -> 0 | P20: ='Stammdaten - Schwimmer'!F22 -> 0 | Q20: 50 | R20: =P20*Q20 -> 0
A21: ='Stammdaten - Schwimmer'!A96 -> 94 | B21: ='Stammdaten - Schwimmer'!B96 -> Kaiser | C21: ='Stammdaten - Schwimmer'!C96 -> Denis | D21: ='Stammdaten - Schwimmer'!D96 -> 40592 | E21: ='Stammdaten - Schwimmer'!E96 -> 502 | F21: ='Stammdaten - Schwimmer'!F96 -> 34 | K21: ='Stammdaten - Schwimmer'!A23 -> 21 | L21: ='Stammdaten - Schwimmer'!B23 -> 0 | M21: ='Stammdaten - Schwimmer'!C23 -> 0 | N21: ='Stammdaten - Schwimmer'!D23 -> 0 | O21: ='Stammdaten - Schwimmer'!E23 -> 0 | P21: ='Stammdaten - Schwimmer'!F23 -> 0 | Q21: 50 | R21: =P21*Q21 -> 0
A22: ='Stammdaten - Schwimmer'!A85 -> 83 | B22: ='Stammdaten - Schwimmer'!B85 -> Heineke | C22: ='Stammdaten - Schwimmer'!C85 -> Jana | D22: ='Stammdaten - Schwimmer'!D85 -> 40445 | E22: ='Stammdaten - Schwimmer'!E85 -> 503 | F22: ='Stammdaten - Schwimmer'!F85 -> 64 | K22: ='Stammdaten - Schwimmer'!A24 -> 22 | L22: ='Stammdaten - Schwimmer'!B24 -> 0 | M22: ='Stammdaten - Schwimmer'!C24 -> 0 | N22: ='Stammdaten - Schwimmer'!D24 -> 0 | O22: ='Stammdaten - Schwimmer'!E24 -> 0 | P22: ='Stammdaten - Schwimmer'!F24 -> 0 | Q22: 50 | R22: =P22*Q22 -> 0
A23: =#REF! -> #REF! | B23: =#REF! -> #REF! | C23: =#REF! -> #REF! | D23: =#REF! -> #REF! | E23: =#REF! -> #REF! | F23: =#REF! -> #REF! | K23: ='Stammdaten - Schwimmer'!A25 -> 23 | L23: ='Stammdaten - Schwimmer'!B25 -> 0 | M23: ='Stammdaten - Schwimmer'!C25 -> 0 | N23: ='Stammdaten - Schwimmer'!D25 -> 0 | O23: ='Stammdaten - Schwimmer'!E25 -> 0 | P23: ='Stammdaten - Schwimmer'!F25 -> 0 | Q23: 25 | R23: =P23*Q23 -> 0
A24: ='Stammdaten - Schwimmer'!A8 -> 6 | B24: ='Stammdaten - Schwimmer'!B8 -> Künsemüller | C24: ='Stammdaten - Schwimmer'!C8 -> Viktoria | D24: ='Stammdaten - Schwimmer'!D8 -> 40021 | E24: ='Stammdaten - Schwimmer'!E8 -> 503 | F24: ='Stammdaten - Schwimmer'!F8 -> 58 | K24: ='Stammdaten - Schwimmer'!A26 -> 24 | L24: ='Stammdaten - Schwimmer'!B26 -> 0 | M24: ='Stammdaten - Schwimmer'!C26 -> 0 | N24: ='Stammdaten - Schwimmer'!D26 -> 0 | O24: ='Stammdaten - Schwimmer'!E26 -> 0 | P24: ='Stammdaten - Schwimmer'!F26 -> 0 | Q24: 25 | R24: =P24*Q24 -> 0
A25: ='Stammdaten - Schwimmer'!A77 -> 75 | B25: ='Stammdaten - Schwimmer'!B77 -> Buck | C25: ='Stammdaten - Schwimmer'!C77 -> Annika | D25: ='Stammdaten - Schwimmer'!D77 -> 39204 | E25: ='Stammdaten - Schwimmer'!E77 -> 502 | F25: ='Stammdaten - Schwimmer'!F77 -> 44 | K25: ='Stammdaten - Schwimmer'!A27 -> 25 | L25: ='Stammdaten - Schwimmer'!B27 -> 0 | M25: ='Stammdaten - Schwimmer'!C27 -> 0 | N25: ='Stammdaten - Schwimmer'!D27 -> 0 | O25: ='Stammdaten - Schwimmer'!E27 -> 0 | P25: ='Stammdaten - Schwimmer'!F27 -> 0 | Q25: 25 | R25: =P25*Q25 -> 0
A26: ='Stammdaten - Schwimmer'!A28 -> 26 | B26: ='Stammdaten - Schwimmer'!B28 -> Bauer | C26: ='Stammdaten - Schwimmer'!C28 -> Tim | D26: ='Stammdaten - Schwimmer'!D28 -> 35823 | E26: ='Stammdaten - Schwimmer'!E28 -> 503 | F26: ='Stammdaten - Schwimmer'!F28 -> 58 | K26: ='Stammdaten - Schwimmer'!A28 -> 26 | L26: ='Stammdaten - Schwimmer'!B28 -> Bauer | M26: ='Stammdaten - Schwimmer'!C28 -> Tim | N26: ='Stammdaten - Schwimmer'!D28 -> 35823 | O26: ='Stammdaten - Schwimmer'!E28 -> 503 | P26: ='Stammdaten - Schwimmer'!F28 -> 58 | Q26: 25 | R26: =P26*Q26 -> 1450
A27: ='Stammdaten - Schwimmer'!A81 -> 79 | B27: ='Stammdaten - Schwimmer'!B81 -> Fritz | C27: ='Stammdaten - Schwimmer'!C81 -> Lukas | D27: ='Stammdaten - Schwimmer'!D81 -> 35085 | E27: ='Stammdaten - Schwimmer'!E81 -> 0 | F27: ='Stammdaten - Schwimmer'!F81 -> 46 | K27: ='Stammdaten - Schwimmer'!A29 -> 27 | L27: ='Stammdaten - Schwimmer'!B29 -> 0 | M27: ='Stammdaten - Schwimmer'!C29 -> 0 | N27: ='Stammdaten - Schwimmer'!D29 -> 0 | O27: ='Stammdaten - Schwimmer'!E29 -> 0 | P27: ='Stammdaten - Schwimmer'!F29 -> 0 | Q27: 25 | R27: =P27*Q27 -> 0
A28: ='Stammdaten - Schwimmer'!A99 -> 97 | B28: ='Stammdaten - Schwimmer'!B99 -> Graf | C28: ='Stammdaten - Schwimmer'!C99 -> Alexander | D28: ='Stammdaten - Schwimmer'!D99 -> 33386 | E28: ='Stammdaten - Schwimmer'!E99 -> 502 | F28: ='Stammdaten - Schwimmer'!F99 -> 24 | K28: ='Stammdaten - Schwimmer'!A30 -> 28 | L28: ='Stammdaten - Schwimmer'!B30 -> 0 | M28: ='Stammdaten - Schwimmer'!C30 -> 0 | N28: ='Stammdaten - Schwimmer'!D30 -> 0 | O28: ='Stammdaten - Schwimmer'!E30 -> 0 | P28: ='Stammdaten - Schwimmer'!F30 -> 0 | Q28: 25 | R28: =P28*Q28 -> 0
A29: ='Stammdaten - Schwimmer'!A80 -> 78 | B29: ='Stammdaten - Schwimmer'!B80 -> B | C29: ='Stammdaten - Schwimmer'!C80 -> Pascal | D29: ='Stammdaten - Schwimmer'!D80 -> 32874 | E29: ='Stammdaten - Schwimmer'!E80 -> 503.504 | F29: ='Stammdaten - Schwimmer'!F80 -> 50 | K29: ='Stammdaten - Schwimmer'!A31 -> 29 | L29: ='Stammdaten - Schwimmer'!B31 -> 0 | M29: ='Stammdaten - Schwimmer'!C31 -> 0 | N29: ='Stammdaten - Schwimmer'!D31 -> 0 | O29: ='Stammdaten - Schwimmer'!E31 -> 0 | P29: ='Stammdaten - Schwimmer'!F31 -> 0 | Q29: 25 | R29: =P29*Q29 -> 0
A30: ='Stammdaten - Schwimmer'!A76 -> 74 | B30: ='Stammdaten - Schwimmer'!B76 -> Schmid | C30: ='Stammdaten - Schwimmer'!C76 -> Katharina | D30: ='Stammdaten - Schwimmer'!D76 -> 30595 | E30: ='Stammdaten - Schwimmer'!E76 -> 502 | F30: ='Stammdaten - Schwimmer'!F76 -> 44 | K30: ='Stammdaten - Schwimmer'!A32 -> 30 | L30: ='Stammdaten - Schwimmer'!B32 -> Kombacher | M30: ='Stammdaten - Schwimmer'!C32 -> Mia | N30: ='Stammdaten - Schwimmer'!D32 -> 43635 | O30: ='Stammdaten - Schwimmer'!E32 -> 502 | P30: ='Stammdaten - Schwimmer'!F32 -> 40 | Q30: 50 | R30: =P30*Q30 -> 2000
A31: ='Stammdaten - Schwimmer'!A33 -> 31 | B31: ='Stammdaten - Schwimmer'!B33 -> Kombacher | C31: ='Stammdaten - Schwimmer'!C33 -> Anja | D31: ='Stammdaten - Schwimmer'!D33 -> 30515 | E31: ='Stammdaten - Schwimmer'!E33 -> 502 | F31: ='Stammdaten - Schwimmer'!F33 -> 46 | K31: ='Stammdaten - Schwimmer'!A33 -> 31 | L31: ='Stammdaten - Schwimmer'!B33 -> Kombacher | M31: ='Stammdaten - Schwimmer'!C33 -> Anja | N31: ='Stammdaten - Schwimmer'!D33 -> 30515 | O31: ='Stammdaten - Schwimmer'!E33 -> 502 | P31: ='Stammdaten - Schwimmer'!F33 -> 46 | Q31: 25 | R31: =P31*Q31 -> 1150
A32: ='Stammdaten - Schwimmer'!A74 -> 72 | B32: ='Stammdaten - Schwimmer'!B74 -> Schmid | C32: ='Stammdaten - Schwimmer'!C74 -> Annette | D32: ='Stammdaten - Schwimmer'!D74 -> 30400 | E32: ='Stammdaten - Schwimmer'!E74 -> 503 | F32: ='Stammdaten - Schwimmer'!F74 -> 44 | K32: ='Stammdaten - Schwimmer'!A34 -> 32 | L32: ='Stammdaten - Schwimmer'!B34 -> 0 | M32: ='Stammdaten - Schwimmer'!C34 -> 0 | N32: ='Stammdaten - Schwimmer'!D34 -> 0 | O32: ='Stammdaten - Schwimmer'!E34 -> 0 | P32: ='Stammdaten - Schwimmer'!F34 -> 0 | Q32: 25 | R32: =P32*Q32 -> 0
A33: ='Stammdaten - Schwimmer'!A49 -> 47 | B33: ='Stammdaten - Schwimmer'!B49 -> Holste | C33: ='Stammdaten - Schwimmer'!C49 -> Ruben | D33: ='Stammdaten - Schwimmer'!D49 -> 30358 | E33: ='Stammdaten - Schwimmer'!E49 -> 503 | F33: ='Stammdaten - Schwimmer'!F49 -> 62 | K33: ='Stammdaten - Schwimmer'!A35 -> 33 | L33: ='Stammdaten - Schwimmer'!B35 -> Kombacher | M33: ='Stammdaten - Schwimmer'!C35 -> Lea | N33: ='Stammdaten - Schwimmer'!D35 -> 41712 | O33: ='Stammdaten - Schwimmer'!E35 -> 502 | P33: ='Stammdaten - Schwimmer'!F35 -> 54 | Q33: 50 | R33: =P33*Q33 -> 2700
A34: ='Stammdaten - Schwimmer'!A95 -> 93 | B34: ='Stammdaten - Schwimmer'!B95 -> Weber-Bleyle | C34: ='Stammdaten - Schwimmer'!C95 -> Christina | D34: ='Stammdaten - Schwimmer'!D95 -> 29077 | E34: ='Stammdaten - Schwimmer'!E95 -> 0 | F34: ='Stammdaten - Schwimmer'!F95 -> 48 | K34: ='Stammdaten - Schwimmer'!A36 -> 34 | L34: ='Stammdaten - Schwimmer'!B36 -> 0 | M34: ='Stammdaten - Schwimmer'!C36 -> 0 | N34: ='Stammdaten - Schwimmer'!D36 -> 0 | O34: ='Stammdaten - Schwimmer'!E36 -> 0 | P34: ='Stammdaten - Schwimmer'!F36 -> 0 | Q34: 50 | R34: =P34*Q34 -> 0
A35: ='Stammdaten - Schwimmer'!A97 -> 95 | B35: ='Stammdaten - Schwimmer'!B97 -> Kaiser | C35: ='Stammdaten - Schwimmer'!C97 -> Vitalis | D35: ='Stammdaten - Schwimmer'!D97 -> 27608 | E35: ='Stammdaten - Schwimmer'!E97 -> 502 | F35: ='Stammdaten - Schwimmer'!F97 -> 24 | K35: ='Stammdaten - Schwimmer'!A37 -> 35 | L35: ='Stammdaten - Schwimmer'!B37 -> Kombacher | M35: ='Stammdaten - Schwimmer'!C37 -> Sara | N35: ='Stammdaten - Schwimmer'!D37 -> 42528 | O35: ='Stammdaten - Schwimmer'!E37 -> 502 | P35: ='Stammdaten - Schwimmer'!F37 -> 84 | Q35: 25 | R35: =P35*Q35 -> 2100
A36: ='Stammdaten - Schwimmer'!A87 -> 85 | B36: ='Stammdaten - Schwimmer'!B87 -> Fernandez | C36: ='Stammdaten - Schwimmer'!C87 -> Silvia Velesco | D36: ='Stammdaten - Schwimmer'!D87 -> 26482 | E36: ='Stammdaten - Schwimmer'!E87 -> 0 | F36: ='Stammdaten - Schwimmer'!F87 -> 32 | K36: ='Stammdaten - Schwimmer'!A38 -> 36 | L36: ='Stammdaten - Schwimmer'!B38 -> 0 | M36: ='Stammdaten - Schwimmer'!C38 -> 0 | N36: ='Stammdaten - Schwimmer'!D38 -> 0 | O36: ='Stammdaten - Schwimmer'!E38 -> 0 | P36: ='Stammdaten - Schwimmer'!F38 -> 0 | Q36: 50 | R36: =P36*Q36 -> 0
A37: ='Stammdaten - Schwimmer'!A88 -> 86 | B37: ='Stammdaten - Schwimmer'!B88 -> Collmer | C37: ='Stammdaten - Schwimmer'!C88 -> Andreas | D37: ='Stammdaten - Schwimmer'!D88 -> 25976 | E37: ='Stammdaten - Schwimmer'!E88 -> 0 | F37: ='Stammdaten - Schwimmer'!F88 -> 52 | K37: ='Stammdaten - Schwimmer'!A39 -> 37 | L37: ='Stammdaten - Schwimmer'!B39 -> 0 | M37: ='Stammdaten - Schwimmer'!C39 -> 0 | N37: ='Stammdaten - Schwimmer'!D39 -> 0 | O37: ='Stammdaten - Schwimmer'!E39 -> 0 | P37: ='Stammdaten - Schwimmer'!F39 -> 0 | Q37: 50 | R37: =P37*Q37 -> 0
A38: ='Stammdaten - Schwimmer'!A91 -> 89 | B38: ='Stammdaten - Schwimmer'!B91 -> Sommerfeld | C38: ='Stammdaten - Schwimmer'!C91 -> Andreas | D38: ='Stammdaten - Schwimmer'!D91 -> 22924 | E38: ='Stammdaten - Schwimmer'!E91 -> 0 | F38: ='Stammdaten - Schwimmer'!F91 -> 42 | K38: ='Stammdaten - Schwimmer'!A40 -> 38 | L38: ='Stammdaten - Schwimmer'!B40 -> 0 | M38: ='Stammdaten - Schwimmer'!C40 -> 0 | N38: ='Stammdaten - Schwimmer'!D40 -> 0 | O38: ='Stammdaten - Schwimmer'!E40 -> 0 | P38: ='Stammdaten - Schwimmer'!F40 -> 0 | Q38: 50 | R38: =P38*Q38 -> 0
A39: ='Stammdaten - Schwimmer'!A92 -> 90 | B39: ='Stammdaten - Schwimmer'!B92 -> Warlitz | C39: ='Stammdaten - Schwimmer'!C92 -> Eleanor | D39: ='Stammdaten - Schwimmer'!D92 -> 22647 | E39: ='Stammdaten - Schwimmer'!E92 -> 0 | F39: ='Stammdaten - Schwimmer'!F92 -> 44 | K39: ='Stammdaten - Schwimmer'!A41 -> 39 | L39: ='Stammdaten - Schwimmer'!B41 -> 0 | M39: ='Stammdaten - Schwimmer'!C41 -> 0 | N39: ='Stammdaten - Schwimmer'!D41 -> 0 | O39: ='Stammdaten - Schwimmer'!E41 -> 0 | P39: ='Stammdaten - Schwimmer'!F41 -> 0 | Q39: 50 | R39: =P39*Q39 -> 0
A40: ='Stammdaten - Schwimmer'!A72 -> 70 | B40: ='Stammdaten - Schwimmer'!B72 -> Klick | C40: ='Stammdaten - Schwimmer'!C72 -> Karin | D40: ='Stammdaten - Schwimmer'!D72 -> 22319 | E40: ='Stammdaten - Schwimmer'!E72 -> 508 | F40: ='Stammdaten - Schwimmer'!F72 -> 36 | K40: ='Stammdaten - Schwimmer'!A42 -> 40 | L40: ='Stammdaten - Schwimmer'!B42 -> 0 | M40: ='Stammdaten - Schwimmer'!C42 -> 0 | N40: ='Stammdaten - Schwimmer'!D42 -> 0 | O40: ='Stammdaten - Schwimmer'!E42 -> 0 | P40: ='Stammdaten - Schwimmer'!F42 -> 0 | Q40: 50 | R40: =P40*Q40 -> 0
...

Sheet Stammdaten - Sponsoren
A1: Sponsoren (bis zu 100 Sponsoren vorgesehen)
A3: Nummer | B3: Name / Unternehmen | C3: Vorname / Vertreter | D3: Adresse | E3: Max. Betrag | F3: Gesponsorte Schwimmer / Mannschaft | H3: Gesponsorte Schwimmer / Mannschaft | I3: Gesponsorte Schwimmer / Mannschaft | J3: Gesponsorte Schwimmer / Mannschaft | K3: Gesponsorte Schwimmer / Mannschaft | L3: Gesponsorte Schwimmer / Mannschaft | M3: Gesponsorte Schwimmer / Mannschaft | N3: Gesponsorte Schwimmer / Mannschaft
A4: 1001 | B4: Förderverein ETB | C4: Thomas Schmid
A5: 1002 | B5: DLRG OG VAI | C5: Thomas Schmid | D5: Walter-de-Pay Str.; Vaihingen (Enz) | F5: 502 | H5: 33 | I5: 30 | J5: 31 | K5: 35 | L5: 72 | M5: 74 | N5: 75 | O5: 50 | P5: 77 | Q5: 79 | R5: 94 | S5: 95 | T5: 97
A6: 1003 | B6: TVV Schwimmabteilung | C6: Tim Bauer | D6: Walter-de-Pay Str.; 71665 Vaihingen | F6: 503 | H6: 9 | I6: 6 | J6: 5 | K6: 77 | L6: 78 | M6: 81 | N6: 82 | O6: 83 | P6: 84 | Q6: 91 | R6: 26
A7: 1004 | B7: Symmetree GmbH | C7: James Hartman | D7: Königstr. 26; 70173 Stuttgart | F7: 504 | H7: 78
A8: 1005 | B8: Kanuclub CJD kaltenstein | C8: Michael Fischer | D8: Klaiberstr 7/1 71665 Vaihingen Enz | F8: 505 | H8: 5 | I8: 87 | J8: 88
A9: 1006 | B9: Auto Service Frank Striebel | C9: Frank Striebel | D9: Römerstr 28, 74399 Walheim | F9: 2
A10: 1007 | B10: Grambow | C10: Kerstin | D10: Weidenweg 10 71665 Vaihingen Enz | F10: 2
A11: 1022 | B11: Seel | C11: Rita | D11: Dürer Ring 22 74372 Serseim | E11: 50 | F11: 30 | G11: 31 | H11: 33 | I11: 35
A12: 1023 | B12: Kombächer | C12: Dagmar | D12: Zur Talwiese24 57334 Bad Laasphe | E12: 50 | F12: 30 | G12: 31 | H12: 33 | I12: 35
A13: 1024 | B13: Häcker | C13: Rudi | D13: Jahnstr. 32 74371 sersheim | E13: 50 | F13: 30 | G13: 31 | H13: 33 | I13: 35
A14: 1034 | B14: Ludwig | C14: Martin | D14: Weizenstr 36 71665 Vaihingn Enz | F14: 50
A15: 1108 | B15: Zimmermann | C15: Inge | D15: Klaiberstr. 7 71665 | F15: 71
A16: 1109 | B16: Klich | C16: Karin | D16: Klaiberstr. 9 71665 | F16: 70
A17: 1110 | B17: RINK | C17: Bärbel | D17: Eugen Eisele Weg 8 | F17: 5 | G17: 77
A18: 1111 | B18: Fischer | C18: Michael Fischer | D18: Klaiberstr. 7/1 | F18: 5 | G18: 77
A19: 1115 | B19: Faigle | C19: Gustav | D19: Einsteinstr. 10 71665 | F19: 72
A20: 1117 | B20: Schmid | C20: Christina | D20: Kalkäckerstr. 9 | F20: 74
A21: 1118 | B21: Schüle | C21: Else | D21: Lindenstr. 27 71665 | F21: 75
A22: 1119 | B22: Buell | C22: Dorothee | D22: Grempstr 38 71665 | F22: 75
A23: 1121 | B23: Wohlers | C23: Jan | D23: Alter Ziegeleiweg 9/1 71665 | F23: 76
A24: 1123 | B24: Fritz | C24: Lukas | D24: Sophie-Scholl-tr. 44 74372 Sersheim | F24: 79
A25: 1124 | B25: Franz | C25: Franziska | D25: Kehlstr. 27 71665 | F25: 80
A26: 1126 | B26: Mauer | C26: familie | D26: Furthbergstr. 56 71665 | F26: 84 | G26: 81
A27: 1127 | B27: Collmer | C27: Andreas | D27: Eichendorffstr.18 71665 | F27: 85
A28: 1128 | B28: Valesco | C28: Silvia | D28: Eichendorffstr. 18 71665 | F28: 86
A29: 1129 | B29: Tutsch | C29: Daniel | F29: 87 | G29: 88
A30: 1130 | B30: Weingartner | C30: Sibyllle | D30: Gerokstr. 41 71665 | F30: 91
A31: 1131 | B31: Glaser | D31: Im Nonnenpfad 11 71706 Markgröningen | F31: 73
A32: 1132 | B32: Irion | C32: Christoph | D32: Teitsteige 5 Aurich | F32: 99
A33: 1133 | B33: Hornbach-Kasswm | D33: Jauerninger Str. 9 | F33: 94 | G33: 95
A48: 1048
A49: 1049
A50: 1050
A51: 1051
A52: 1052
A53: 1053
A54: 1054
A55: 1055
...

Sheet Stammdaten Teams
A1: Team Zusammenstetzungen
A2: (bis zu 25 Schwimmer im Team und bis zu 50 Teams vorgesehen)
A3: Team Nummer | B3: Team Name | C3: Verantwortlicher | D3: Gesamt Mitglieder | E3: Gesamtanzahl Bahnen | F3: Spende pro Bahn | G3: Spenden- Betrag | H3: Bahnen pro Mitglied | I3: Zugehöriger Schwimmer | J3: Zugehöriger Schwimmer | K3: Zugehöriger Schwimmer | L3: Zugehöriger Schwimmer | M3: Zugehöriger Schwimmer | N3: Zugehöriger Schwimmer | O3: Zugehöriger Schwimmer | P3: Zugehöriger Schwimmer | Q3: Zugehöriger Schwimmer | R3: Zugehöriger Schwimmer | S3: Zugehöriger Schwimmer | T3: Zugehöriger Schwimmer | U3: Zugehöriger Schwimmer | V3: Zugehöriger Schwimmer | W3: Zugehöriger Schwimmer | X3: Zugehöriger Schwimmer | Y3: Zugehöriger Schwimmer | Z3: Zugehöriger Schwimmer | AA3: Zugehöriger Schwimmer | AB3: Zugehöriger Schwimmer | AC3: Zugehöriger Schwimmer | AD3: Zugehöriger Schwimmer | AE3: Zugehöriger Schwimmer | AF3: Zugehöriger Schwimmer | AG3: Zugehöriger Schwimmer
A4: 501 | B4: FV ETB | D4: =COUNTIF(I4:AQ4,">0") -> 0 | H4: =IF(D4>0,E4/D4,) -> 0
A5: 502 | B5: DLRG | C5: Thomas Schmid | D5: =COUNTIFS(I5:AQ5,">0",I5:AQ5,"<101") -> 11 | E5: =SUMIF('Stammdaten - Schwimmer'!G$4:G$99,'Stammdaten - Sponsoren'!A5,'Stammdaten - Schwimmer'!F$4:F$99)+SUMIF('Stammdaten - Schwimmer'!K$4:K$99,'Stammdaten - Sponsoren'!A5,'Stammdaten - Schwimmer'!F$4:F$99)+SUMIF('Stammdaten - Schwimmer'!O$4:O$99,'Stammdaten - Sponsoren'!A5,'Stammdaten - Schwimmer'!F$4:F$99)+SUMIF('Stammdaten - Schwimmer'!S$4:S$99,'Stammdaten - Sponsoren'!A5,'Stammdaten - Schwimmer'!F$4:F$99) -> 448 | F5: 0.5 | G5: =E5*F5 -> 224 | H5: =IF(D5>0,E5/D5,) -> 40.727273 | I5: 26 | J5: 30 | K5: 31 | L5: 33 | M5: 35 | N5: 47 | O5: 74 | P5: 75 | Q5: 94 | R5: 95 | S5: 97 | T5: 101 | U5: 101 | V5: 101 | W5: 101 | X5: 101 | Y5: 101 | Z5: 101 | AA5: 101 | AB5: 101 | AC5: 101 | AD5: 101 | AE5: 101 | AF5: 101 | AG5: 101 | AH5: 101 | AI5: 101 | AJ5: 101 | AK5: 101 | AL5: 101 | AM5: 101 | AN5: 101 | AO5: 101 | AP5: 101
A6: 503 | B6: TVV Schwimm | C6: Tim Bauer | D6: =COUNTIFS(I6:AQ6,">0",I6:AQ6,"<101") -> 13 | E6: =SUMIF('Stammdaten - Schwimmer'!G$4:G$99,'Stammdaten - Sponsoren'!A6,'Stammdaten - Schwimmer'!F$4:F$99)+SUMIF('Stammdaten - Schwimmer'!K$4:K$99,'Stammdaten - Sponsoren'!A6,'Stammdaten - Schwimmer'!F$4:F$99)+SUMIF('Stammdaten - Schwimmer'!O$4:O$99,'Stammdaten - Sponsoren'!A6,'Stammdaten - Schwimmer'!F$4:F$99)+SUMIF('Stammdaten - Schwimmer'!S$4:S$99,'Stammdaten - Sponsoren'!A6,'Stammdaten - Schwimmer'!F$4:F$99) -> 800 | F6: 0.5 | G6: =E6*F6 -> 400 | H6: =IF(D6>0,E6/D6,) -> 61.538462 | I6: 5 | J6: 6 | K6: 9 | L6: 26 | M6: 47 | N6: 72 | O6: 77 | P6: 78 | Q6: 81 | R6: 82 | S6: 83 | T6: 84 | U6: 99 | V6: 101 | W6: 101 | X6: 101 | Y6: 101 | Z6: 101 | AA6: 101 | AB6: 101 | AC6: 101 | AD6: 101 | AE6: 101 | AF6: 101 | AG6: 101 | AH6: 101 | AI6: 101 | AJ6: 101 | AK6: 101 | AL6: 101 | AM6: 101 | AN6: 101 | AO6: 101 | AP6: 101
A7: 504 | B7: Schildkröten | C7: Symmetree GmbH | D7: =COUNTIFS(I7:AQ7,">0",I7:AQ7,"<101") -> 2 | E7: =SUMIF('Stammdaten - Schwimmer'!G$4:G$99,'Stammdaten - Sponsoren'!A7,'Stammdaten - Schwimmer'!F$4:F$99)+SUMIF('Stammdaten - Schwimmer'!K$4:K$99,'Stammdaten - Sponsoren'!A7,'Stammdaten - Schwimmer'!F$4:F$99)+SUMIF('Stammdaten - Schwimmer'!O$4:O$99,'Stammdaten - Sponsoren'!A7,'Stammdaten - Schwimmer'!F$4:F$99)+SUMIF('Stammdaten - Schwimmer'!S$4:S$99,'Stammdaten - Sponsoren'!A7,'Stammdaten - Schwimmer'!F$4:F$99) -> 50 | F7: 0.5 | G7: =E7*F7 -> 25 | H7: =IF(D7>0,E7/D7,) -> 25 | I7: 78 | J7: 99 | K7: 101 | L7: 101 | M7: 101 | N7: 101 | O7: 101 | P7: 101 | Q7: 101 | R7: 101 | S7: 101 | T7: 101 | U7: 101 | V7: 101 | W7: 101 | X7: 101 | Y7: 101 | Z7: 101 | AA7: 101 | AB7: 101 | AC7: 101 | AD7: 101 | AE7: 101 | AF7: 101 | AG7: 101 | AH7: 101 | AI7: 101 | AJ7: 101 | AK7: 101 | AL7: 101 | AM7: 101 | AN7: 101 | AO7: 101 | AP7: 101
A8: 505 | B8: Kanu Klub | C8: Michael Fischer | D8: =COUNTIFS(I8:AQ8,">0",I8:AQ8,"<101") -> 4 | E8: =SUMIF('Stammdaten - Schwimmer'!G$4:G$99,'Stammdaten - Sponsoren'!A8,'Stammdaten - Schwimmer'!F$4:F$99)+SUMIF('Stammdaten - Schwimmer'!K$4:K$99,'Stammdaten - Sponsoren'!A8,'Stammdaten - Schwimmer'!F$4:F$99)+SUMIF('Stammdaten - Schwimmer'!O$4:O$99,'Stammdaten - Sponsoren'!A8,'Stammdaten - Schwimmer'!F$4:F$99)+SUMIF('Stammdaten - Schwimmer'!S$4:S$99,'Stammdaten - Sponsoren'!A8,'Stammdaten - Schwimmer'!F$4:F$99) -> 292 | F8: 0.5 | G8: =E8*F8 -> 146 | H8: =IF(D8>0,E8/D8,) -> 73 | I8: 5 | J8: 77 | K8: 87 | L8: 88 | M8: 101 | N8: 101 | O8: 101 | P8: 101 | Q8: 101 | R8: 101 | S8: 101 | T8: 101 | U8: 101 | V8: 101 | W8: 101 | X8: 101 | Y8: 101 | Z8: 101 | AA8: 101 | AB8: 101 | AC8: 101 | AD8: 101 | AE8: 101 | AF8: 101 | AG8: 101 | AH8: 101 | AI8: 101 | AJ8: 101 | AK8: 101 | AL8: 101 | AM8: 101 | AN8: 101 | AO8: 101 | AP8: 101
A9: 506 | B9: DRK Ortsverein VAI | C9: Eliase Flohr | D9: =COUNTIFS(I9:AQ9,">0",I9:AQ9,"<101") -> 0 | E9: =INDIRECT("'Stammdaten - Schwimmer'!F"&(I9+3))+INDIRECT("'Stammdaten - Schwimmer'!F"&(J9+3))+INDIRECT("'Stammdaten - Schwimmer'!F"&(K9+3))+INDIRECT("'Stammdaten - Schwimmer'!F"&(L9+3))+INDIRECT("'Stammdaten - Schwimmer'!F"&(M9+3))+INDIRECT("'Stammdaten - Schwimmer'!F"&(N9+3))+INDIRECT("'Stammdaten - Schwimmer'!F"&O9+3)+INDIRECT("'Stammdaten - Schwimmer'!F"&(P9+3))+INDIRECT("'Stammdaten - Schwimmer'!F"&(Q9+3))+INDIRECT("'Stammdaten - Schwimmer'!F"&(R9+3))+INDIRECT("'Stammdaten - Schwimmer'!F"&(S9+3))+INDIRECT("'Stammdaten - Schwimmer'!F"&(T9+3))+INDIRECT("'Stammdaten - Schwimmer'!F"&(U9+3))+INDIRECT("'Stammdaten - Schwimmer'!F"&(V9+3))+INDIRECT("'Stammdaten - Schwimmer'!F"&(W9+3))+INDIRECT("'Stammdaten - Schwimmer'!F"&(X9+3))+INDIRECT("'Stammdaten - Schwimmer'!F"&(Y9+3))+INDIRECT("'Stammdaten - Schwimmer'!F"&(Z9+3))+INDIRECT("'Stammdaten - Schwimmer'!F"&(AA9+3))+INDIRECT("'Stammdaten - Schwimmer'!F"&(AB9+3))+INDIRECT("'Stammdaten - Schwimmer'!F"&(AC9+3))+INDIRECT("'Stammdaten - Schwimmer'!F"&(AD9+3))+INDIRECT("'Stammdaten - Schwimmer'!F"&(AE9+3))+INDIRECT("'Stammdaten - Schwimmer'!F"&(AF9+3))+INDIRECT("'Stammdaten - Schwimmer'!F"&(AG9+3)) -> 0 | G9: =E9*F9 -> 0 | H9: =IF(D9>0,E9/D9,) -> 0 | I9: 101 | J9: 101 | K9: 101 | L9: 101 | M9: 101 | N9: 101 | O9: 101 | P9: 101 | Q9: 101 | R9: 101 | S9: 101 | T9: 101 | U9: 101 | V9: 101 | W9: 101 | X9: 101 | Y9: 101 | Z9: 101 | AA9: 101 | AB9: 101 | AC9: 101 | AD9: 101 | AE9: 101 | AF9: 101 | AG9: 101 | AH9: 101 | AI9: 101 | AJ9: 101 | AK9: 101 | AL9: 101 | AM9: 101 | AN9: 101
A10: 507 | B10: Die Hydrotherapeuten | C10: Warner, Chris | D10: =COUNTIFS(I10:AQ10,">0",I10:AQ10,"<101") -> 0 | E10: =INDIRECT("'Stammdaten - Schwimmer'!F"&(I10+3))+INDIRECT("'Stammdaten - Schwimmer'!F"&(J10+3))+INDIRECT("'Stammdaten - Schwimmer'!F"&(K10+3))+INDIRECT("'Stammdaten - Schwimmer'!F"&(L10+3))+INDIRECT("'Stammdaten - Schwimmer'!F"&(M10+3))+INDIRECT("'Stammdaten - Schwimmer'!F"&(N10+3))+INDIRECT("'Stammdaten - Schwimmer'!F"&O10+3)+INDIRECT("'Stammdaten - Schwimmer'!F"&(P10+3))+INDIRECT("'Stammdaten - Schwimmer'!F"&(Q10+3))+INDIRECT("'Stammdaten - Schwimmer'!F"&(R10+3))+INDIRECT("'Stammdaten - Schwimmer'!F"&(S10+3))+INDIRECT("'Stammdaten - Schwimmer'!F"&(T10+3))+INDIRECT("'Stammdaten - Schwimmer'!F"&(U10+3))+INDIRECT("'Stammdaten - Schwimmer'!F"&(V10+3))+INDIRECT("'Stammdaten - Schwimmer'!F"&(W10+3))+INDIRECT("'Stammdaten - Schwimmer'!F"&(X10+3))+INDIRECT("'Stammdaten - Schwimmer'!F"&(Y10+3))+INDIRECT("'Stammdaten - Schwimmer'!F"&(Z10+3))+INDIRECT("'Stammdaten - Schwimmer'!F"&(AA10+3))+INDIRECT("'Stammdaten - Schwimmer'!F"&(AB10+3))+INDIRECT("'Stammdaten - Schwimmer'!F"&(AC10+3))+INDIRECT("'Stammdaten - Schwimmer'!F"&(AD10+3))+INDIRECT("'Stammdaten - Schwimmer'!F"&(AE10+3))+INDIRECT("'Stammdaten - Schwimmer'!F"&(AF10+3))+INDIRECT("'Stammdaten - Schwimmer'!F"&(AG10+3)) -> 0 | G10: =E10*F10 -> 0 | H10: =IF(D10>0,E10/D10,) -> 0 | I10: 101 | J10: 101 | K10: 101 | L10: 101 | M10: 101 | N10: 101 | O10: 101 | P10: 101 | Q10: 101 | R10: 101 | S10: 101 | T10: 101 | U10: 101 | V10: 101 | W10: 101 | X10: 101 | Y10: 101 | Z10: 101 | AA10: 101 | AB10: 101 | AC10: 101 | AD10: 101 | AE10: 101 | AF10: 101 | AG10: 101 | AH10: 101 | AI10: 101 | AJ10: 101 | AK10: 101 | AL10: 101 | AM10: 101 | AN10: 101
A11: 508 | B11: Klaiberstr | D11: =COUNTIFS(I11:AQ11,">0",I11:AQ11,"<101") -> 0 | E11: =INDIRECT("'Stammdaten - Schwimmer'!F"&(I11+3))+INDIRECT("'Stammdaten - Schwimmer'!F"&(J11+3))+INDIRECT("'Stammdaten - Schwimmer'!F"&(K11+3))+INDIRECT("'Stammdaten - Schwimmer'!F"&(L11+3))+INDIRECT("'Stammdaten - Schwimmer'!F"&(M11+3))+INDIRECT("'Stammdaten - Schwimmer'!F"&(N11+3))+INDIRECT("'Stammdaten - Schwimmer'!F"&O11+3)+INDIRECT("'Stammdaten - Schwimmer'!F"&(P11+3))+INDIRECT("'Stammdaten - Schwimmer'!F"&(Q11+3))+INDIRECT("'Stammdaten - Schwimmer'!F"&(R11+3))+INDIRECT("'Stammdaten - Schwimmer'!F"&(S11+3))+INDIRECT("'Stammdaten - Schwimmer'!F"&(T11+3))+INDIRECT("'Stammdaten - Schwimmer'!F"&(U11+3))+INDIRECT("'Stammdaten - Schwimmer'!F"&(V11+3))+INDIRECT("'Stammdaten - Schwimmer'!F"&(W11+3))+INDIRECT("'Stammdaten - Schwimmer'!F"&(X11+3))+INDIRECT("'Stammdaten - Schwimmer'!F"&(Y11+3))+INDIRECT("'Stammdaten - Schwimmer'!F"&(Z11+3))+INDIRECT("'Stammdaten - Schwimmer'!F"&(AA11+3))+INDIRECT("'Stammdaten - Schwimmer'!F"&(AB11+3))+INDIRECT("'Stammdaten - Schwimmer'!F"&(AC11+3))+INDIRECT("'Stammdaten - Schwimmer'!F"&(AD11+3))+INDIRECT("'Stammdaten - Schwimmer'!F"&(AE11+3))+INDIRECT("'Stammdaten - Schwimmer'!F"&(AF11+3))+INDIRECT("'Stammdaten - Schwimmer'!F"&(AG11+3)) -> 0 | G11: =E11*F11 -> 0 | H11: =IF(D11>0,E11/D11,) -> 0 | I11: 101 | J11: 101 | K11: 101 | L11: 101 | M11: 101 | N11: 101 | O11: 101 | P11: 101 | Q11: 101 | R11: 101 | S11: 101 | T11: 101 | U11: 101 | V11: 101 | W11: 101 | X11: 101 | Y11: 101 | Z11: 101 | AA11: 101 | AB11: 101 | AC11: 101 | AD11: 101 | AE11: 101 | AF11: 101 | AG11: 101 | AH11: 101 | AI11: 101 | AJ11: 101 | AK11: 101 | AL11: 101 | AM11: 101 | AN11: 101
A12: 509 | D12: =COUNTIFS(I12:AQ12,">0",I12:AQ12,"<101") -> 0 | E12: =INDIRECT("'Stammdaten - Schwimmer'!F"&(I12+3))+INDIRECT("'Stammdaten - Schwimmer'!F"&(J12+3))+INDIRECT("'Stammdaten - Schwimmer'!F"&(K12+3))+INDIRECT("'Stammdaten - Schwimmer'!F"&(L12+3))+INDIRECT("'Stammdaten - Schwimmer'!F"&(M12+3))+INDIRECT("'Stammdaten - Schwimmer'!F"&(N12+3))+INDIRECT("'Stammdaten - Schwimmer'!F"&O12+3)+INDIRECT("'Stammdaten - Schwimmer'!F"&(P12+3))+INDIRECT("'Stammdaten - Schwimmer'!F"&(Q12+3))+INDIRECT("'Stammdaten - Schwimmer'!F"&(R12+3))+INDIRECT("'Stammdaten - Schwimmer'!F"&(S12+3))+INDIRECT("'Stammdaten - Schwimmer'!F"&(T12+3))+INDIRECT("'Stammdaten - Schwimmer'!F"&(U12+3))+INDIRECT("'Stammdaten - Schwimmer'!F"&(V12+3))+INDIRECT("'Stammdaten - Schwimmer'!F"&(W12+3))+INDIRECT("'Stammdaten - Schwimmer'!F"&(X12+3))+INDIRECT("'Stammdaten - Schwimmer'!F"&(Y12+3))+INDIRECT("'Stammdaten - Schwimmer'!F"&(Z12+3))+INDIRECT("'Stammdaten - Schwimmer'!F"&(AA12+3))+INDIRECT("'Stammdaten - Schwimmer'!F"&(AB12+3))+INDIRECT("'Stammdaten - Schwimmer'!F"&(AC12+3))+INDIRECT("'Stammdaten - Schwimmer'!F"&(AD12+3))+INDIRECT("'Stammdaten - Schwimmer'!F"&(AE12+3))+INDIRECT("'Stammdaten - Schwimmer'!F"&(AF12+3))+INDIRECT("'Stammdaten - Schwimmer'!F"&(AG12+3)) -> 0 | G12: =E12*F12 -> 0 | H12: =IF(D12>0,E12/D12,) -> 0 | I12: 101 | J12: 101 | K12: 101 | L12: 101 | M12: 101 | N12: 101 | O12: 101 | P12: 101 | Q12: 101 | R12: 101 | S12: 101 | T12: 101 | U12: 101 | V12: 101 | W12: 101 | X12: 101 | Y12: 101 | Z12: 101 | AA12: 101 | AB12: 101 | AC12: 101 | AD12: 101 | AE12: 101 | AF12: 101 | AG12: 101 | AH12: 101 | AI12: 101 | AJ12: 101 | AK12: 101 | AL12: 101 | AM12: 101 | AN12: 101
A13: 510 | D13: =COUNTIFS(I13:AQ13,">0",I13:AQ13,"<101") -> 0 | E13: =INDIRECT("'Stammdaten - Schwimmer'!F"&(I13+3))+INDIRECT("'Stammdaten - Schwimmer'!F"&(J13+3))+INDIRECT("'Stammdaten - Schwimmer'!F"&(K13+3))+INDIRECT("'Stammdaten - Schwimmer'!F"&(L13+3))+INDIRECT("'Stammdaten - Schwimmer'!F"&(M13+3))+INDIRECT("'Stammdaten - Schwimmer'!F"&(N13+3))+INDIRECT("'Stammdaten - Schwimmer'!F"&O13+3)+INDIRECT("'Stammdaten - Schwimmer'!F"&(P13+3))+INDIRECT("'Stammdaten - Schwimmer'!F"&(Q13+3))+INDIRECT("'Stammdaten - Schwimmer'!F"&(R13+3))+INDIRECT("'Stammdaten - Schwimmer'!F"&(S13+3))+INDIRECT("'Stammdaten - Schwimmer'!F"&(T13+3))+INDIRECT("'Stammdaten - Schwimmer'!F"&(U13+3))+INDIRECT("'Stammdaten - Schwimmer'!F"&(V13+3))+INDIRECT("'Stammdaten - Schwimmer'!F"&(W13+3))+INDIRECT("'Stammdaten - Schwimmer'!F"&(X13+3))+INDIRECT("'Stammdaten - Schwimmer'!F"&(Y13+3))+INDIRECT("'Stammdaten - Schwimmer'!F"&(Z13+3))+INDIRECT("'Stammdaten - Schwimmer'!F"&(AA13+3))+INDIRECT("'Stammdaten - Schwimmer'!F"&(AB13+3))+INDIRECT("'Stammdaten - Schwimmer'!F"&(AC13+3))+INDIRECT("'Stammdaten - Schwimmer'!F"&(AD13+3))+INDIRECT("'Stammdaten - Schwimmer'!F"&(AE13+3))+INDIRECT("'Stammdaten - Schwimmer'!F"&(AF13+3))+INDIRECT("'Stammdaten - Schwimmer'!F"&(AG13+3)) -> 0 | G13: =E13*F13 -> 0 | H13: =IF(D13>0,E13/D13,) -> 0 | I13: 101 | J13: 101 | K13: 101 | L13: 101 | M13: 101 | N13: 101 | O13: 101 | P13: 101 | Q13: 101 | R13: 101 | S13: 101 | T13: 101 | U13: 101 | V13: 101 | W13: 101 | X13: 101 | Y13: 101 | Z13: 101 | AA13: 101 | AB13: 101 | AC13: 101 | AD13: 101 | AE13: 101 | AF13: 101 | AG13: 101 | AH13: 101 | AI13: 101 | AJ13: 101 | AK13: 101 | AL13: 101 | AM13: 101 | AN13: 101
A14: 511 | D14: =COUNTIFS(I14:AQ14,">0",I14:AQ14,"<101") -> 0 | E14: =INDIRECT("'Stammdaten - Schwimmer'!F"&(I14+3))+INDIRECT("'Stammdaten - Schwimmer'!F"&(J14+3))+INDIRECT("'Stammdaten - Schwimmer'!F"&(K14+3))+INDIRECT("'Stammdaten - Schwimmer'!F"&(L14+3))+INDIRECT("'Stammdaten - Schwimmer'!F"&(M14+3))+INDIRECT("'Stammdaten - Schwimmer'!F"&(N14+3))+INDIRECT("'Stammdaten - Schwimmer'!F"&O14+3)+INDIRECT("'Stammdaten - Schwimmer'!F"&(P14+3))+INDIRECT("'Stammdaten - Schwimmer'!F"&(Q14+3))+INDIRECT("'Stammdaten - Schwimmer'!F"&(R14+3))+INDIRECT("'Stammdaten - Schwimmer'!F"&(S14+3))+INDIRECT("'Stammdaten - Schwimmer'!F"&(T14+3))+INDIRECT("'Stammdaten - Schwimmer'!F"&(U14+3))+INDIRECT("'Stammdaten - Schwimmer'!F"&(V14+3))+INDIRECT("'Stammdaten - Schwimmer'!F"&(W14+3))+INDIRECT("'Stammdaten - Schwimmer'!F"&(X14+3))+INDIRECT("'Stammdaten - Schwimmer'!F"&(Y14+3))+INDIRECT("'Stammdaten - Schwimmer'!F"&(Z14+3))+INDIRECT("'Stammdaten - Schwimmer'!F"&(AA14+3))+INDIRECT("'Stammdaten - Schwimmer'!F"&(AB14+3))+INDIRECT("'Stammdaten - Schwimmer'!F"&(AC14+3))+INDIRECT("'Stammdaten - Schwimmer'!F"&(AD14+3))+INDIRECT("'Stammdaten - Schwimmer'!F"&(AE14+3))+INDIRECT("'Stammdaten - Schwimmer'!F"&(AF14+3))+INDIRECT("'Stammdaten - Schwimmer'!F"&(AG14+3)) -> 0 | G14: =E14*F14 -> 0 | H14: =IF(D14>0,E14/D14,) -> 0 | I14: 101 | J14: 101 | K14: 101 | L14: 101 | M14: 101 | N14: 101 | O14: 101 | P14: 101 | Q14: 101 | R14: 101 | S14: 101 | T14: 101 | U14: 101 | V14: 101 | W14: 101 | X14: 101 | Y14: 101 | Z14: 101 | AA14: 101 | AB14: 101 | AC14: 101 | AD14: 101 | AE14: 101 | AF14: 101 | AG14: 101 | AH14: 101 | AI14: 101 | AJ14: 101 | AK14: 101 | AL14: 101 | AM14: 101 | AN14: 101
A15: 512 | D15: =COUNTIFS(I15:AQ15,">0",I15:AQ15,"<101") -> 0 | E15: =INDIRECT("'Stammdaten - Schwimmer'!F"&(I15+3))+INDIRECT("'Stammdaten - Schwimmer'!F"&(J15+3))+INDIRECT("'Stammdaten - Schwimmer'!F"&(K15+3))+INDIRECT("'Stammdaten - Schwimmer'!F"&(L15+3))+INDIRECT("'Stammdaten - Schwimmer'!F"&(M15+3))+INDIRECT("'Stammdaten - Schwimmer'!F"&(N15+3))+INDIRECT("'Stammdaten - Schwimmer'!F"&O15+3)+INDIRECT("'Stammdaten - Schwimmer'!F"&(P15+3))+INDIRECT("'Stammdaten - Schwimmer'!F"&(Q15+3))+INDIRECT("'Stammdaten - Schwimmer'!F"&(R15+3))+INDIRECT("'Stammdaten - Schwimmer'!F"&(S15+3))+INDIRECT("'Stammdaten - Schwimmer'!F"&(T15+3))+INDIRECT("'Stammdaten - Schwimmer'!F"&(U15+3))+INDIRECT("'Stammdaten - Schwimmer'!F"&(V15+3))+INDIRECT("'Stammdaten - Schwimmer'!F"&(W15+3))+INDIRECT("'Stammdaten - Schwimmer'!F"&(X15+3))+INDIRECT("'Stammdaten - Schwimmer'!F"&(Y15+3))+INDIRECT("'Stammdaten - Schwimmer'!F"&(Z15+3))+INDIRECT("'Stammdaten - Schwimmer'!F"&(AA15+3))+INDIRECT("'Stammdaten - Schwimmer'!F"&(AB15+3))+INDIRECT("'Stammdaten - Schwimmer'!F"&(AC15+3))+INDIRECT("'Stammdaten - Schwimmer'!F"&(AD15+3))+INDIRECT("'Stammdaten - Schwimmer'!F"&(AE15+3))+INDIRECT("'Stammdaten - Schwimmer'!F"&(AF15+3))+INDIRECT("'Stammdaten - Schwimmer'!F"&(AG15+3)) -> 0 | G15: =E15*F15 -> 0 | H15: =IF(D15>0,E15/D15,) -> 0 | I15: 101 | J15: 101 | K15: 101 | L15: 101 | M15: 101 | N15: 101 | O15: 101 | P15: 101 | Q15: 101 | R15: 101 | S15: 101 | T15: 101 | U15: 101 | V15: 101 | W15: 101 | X15: 101 | Y15: 101 | Z15: 101 | AA15: 101 | AB15: 101 | AC15: 101 | AD15: 101 | AE15: 101 | AF15: 101 | AG15: 101 | AH15: 101 | AI15: 101 | AJ15: 101 | AK15: 101 | AL15: 101 | AM15: 101 | AN15: 101
A16: 513 | D16: =COUNTIFS(I16:AQ16,">0",I16:AQ16,"<101") -> 0 | E16: =INDIRECT("'Stammdaten - Schwimmer'!F"&(I16+3))+INDIRECT("'Stammdaten - Schwimmer'!F"&(J16+3))+INDIRECT("'Stammdaten - Schwimmer'!F"&(K16+3))+INDIRECT("'Stammdaten - Schwimmer'!F"&(L16+3))+INDIRECT("'Stammdaten - Schwimmer'!F"&(M16+3))+INDIRECT("'Stammdaten - Schwimmer'!F"&(N16+3))+INDIRECT("'Stammdaten - Schwimmer'!F"&O16+3)+INDIRECT("'Stammdaten - Schwimmer'!F"&(P16+3))+INDIRECT("'Stammdaten - Schwimmer'!F"&(Q16+3))+INDIRECT("'Stammdaten - Schwimmer'!F"&(R16+3))+INDIRECT("'Stammdaten - Schwimmer'!F"&(S16+3))+INDIRECT("'Stammdaten - Schwimmer'!F"&(T16+3))+INDIRECT("'Stammdaten - Schwimmer'!F"&(U16+3))+INDIRECT("'Stammdaten - Schwimmer'!F"&(V16+3))+INDIRECT("'Stammdaten - Schwimmer'!F"&(W16+3))+INDIRECT("'Stammdaten - Schwimmer'!F"&(X16+3))+INDIRECT("'Stammdaten - Schwimmer'!F"&(Y16+3))+INDIRECT("'Stammdaten - Schwimmer'!F"&(Z16+3))+INDIRECT("'Stammdaten - Schwimmer'!F"&(AA16+3))+INDIRECT("'Stammdaten - Schwimmer'!F"&(AB16+3))+INDIRECT("'Stammdaten - Schwimmer'!F"&(AC16+3))+INDIRECT("'Stammdaten - Schwimmer'!F"&(AD16+3))+INDIRECT("'Stammdaten - Schwimmer'!F"&(AE16+3))+INDIRECT("'Stammdaten - Schwimmer'!F"&(AF16+3))+INDIRECT("'Stammdaten - Schwimmer'!F"&(AG16+3)) -> 0 | G16: =E16*F16 -> 0 | H16: =IF(D16>0,E16/D16,) -> 0 | I16: 101 | J16: 101 | K16: 101 | L16: 101 | M16: 101 | N16: 101 | O16: 101 | P16: 101 | Q16: 101 | R16: 101 | S16: 101 | T16: 101 | U16: 101 | V16: 101 | W16: 101 | X16: 101 | Y16: 101 | Z16: 101 | AA16: 101 | AB16: 101 | AC16: 101 | AD16: 101 | AE16: 101 | AF16: 101 | AG16: 101 | AH16: 101 | AI16: 101 | AJ16: 101 | AK16: 101 | AL16: 101 | AM16: 101 | AN16: 101
A17: 514 | D17: =COUNTIFS(I17:AQ17,">0",I17:AQ17,"<101") -> 0 | E17: =INDIRECT("'Stammdaten - Schwimmer'!F"&(I17+3))+INDIRECT("'Stammdaten - Schwimmer'!F"&(J17+3))+INDIRECT("'Stammdaten - Schwimmer'!F"&(K17+3))+INDIRECT("'Stammdaten - Schwimmer'!F"&(L17+3))+INDIRECT("'Stammdaten - Schwimmer'!F"&(M17+3))+INDIRECT("'Stammdaten - Schwimmer'!F"&(N17+3))+INDIRECT("'Stammdaten - Schwimmer'!F"&O17+3)+INDIRECT("'Stammdaten - Schwimmer'!F"&(P17+3))+INDIRECT("'Stammdaten - Schwimmer'!F"&(Q17+3))+INDIRECT("'Stammdaten - Schwimmer'!F"&(R17+3))+INDIRECT("'Stammdaten - Schwimmer'!F"&(S17+3))+INDIRECT("'Stammdaten - Schwimmer'!F"&(T17+3))+INDIRECT("'Stammdaten - Schwimmer'!F"&(U17+3))+INDIRECT("'Stammdaten - Schwimmer'!F"&(V17+3))+INDIRECT("'Stammdaten - Schwimmer'!F"&(W17+3))+INDIRECT("'Stammdaten - Schwimmer'!F"&(X17+3))+INDIRECT("'Stammdaten - Schwimmer'!F"&(Y17+3))+INDIRECT("'Stammdaten - Schwimmer'!F"&(Z17+3))+INDIRECT("'Stammdaten - Schwimmer'!F"&(AA17+3))+INDIRECT("'Stammdaten - Schwimmer'!F"&(AB17+3))+INDIRECT("'Stammdaten - Schwimmer'!F"&(AC17+3))+INDIRECT("'Stammdaten - Schwimmer'!F"&(AD17+3))+INDIRECT("'Stammdaten - Schwimmer'!F"&(AE17+3))+INDIRECT("'Stammdaten - Schwimmer'!F"&(AF17+3))+INDIRECT("'Stammdaten - Schwimmer'!F"&(AG17+3)) -> 0 | G17: =E17*F17 -> 0 | H17: =IF(D17>0,E17/D17,) -> 0 | I17: 101 | J17: 101 | K17: 101 | L17: 101 | M17: 101 | N17: 101 | O17: 101 | P17: 101 | Q17: 101 | R17: 101 | S17: 101 | T17: 101 | U17: 101 | V17: 101 | W17: 101 | X17: 101 | Y17: 101 | Z17: 101 | AA17: 101 | AB17: 101 | AC17: 101 | AD17: 101 | AE17: 101 | AF17: 101 | AG17: 101 | AH17: 101 | AI17: 101 | AJ17: 101 | AK17: 101 | AL17: 101 | AM17: 101 | AN17: 101
A18: 515 | D18: =COUNTIFS(I18:AQ18,">0",I18:AQ18,"<101") -> 0 | E18: =INDIRECT("'Stammdaten - Schwimmer'!F"&(I18+3))+INDIRECT("'Stammdaten - Schwimmer'!F"&(J18+3))+INDIRECT("'Stammdaten - Schwimmer'!F"&(K18+3))+INDIRECT("'Stammdaten - Schwimmer'!F"&(L18+3))+INDIRECT("'Stammdaten - Schwimmer'!F"&(M18+3))+INDIRECT("'Stammdaten - Schwimmer'!F"&(N18+3))+INDIRECT("'Stammdaten - Schwimmer'!F"&O18+3)+INDIRECT("'Stammdaten - Schwimmer'!F"&(P18+3))+INDIRECT("'Stammdaten - Schwimmer'!F"&(Q18+3))+INDIRECT("'Stammdaten - Schwimmer'!F"&(R18+3))+INDIRECT("'Stammdaten - Schwimmer'!F"&(S18+3))+INDIRECT("'Stammdaten - Schwimmer'!F"&(T18+3))+INDIRECT("'Stammdaten - Schwimmer'!F"&(U18+3))+INDIRECT("'Stammdaten - Schwimmer'!F"&(V18+3))+INDIRECT("'Stammdaten - Schwimmer'!F"&(W18+3))+INDIRECT("'Stammdaten - Schwimmer'!F"&(X18+3))+INDIRECT("'Stammdaten - Schwimmer'!F"&(Y18+3))+INDIRECT("'Stammdaten - Schwimmer'!F"&(Z18+3))+INDIRECT("'Stammdaten - Schwimmer'!F"&(AA18+3))+INDIRECT("'Stammdaten - Schwimmer'!F"&(AB18+3))+INDIRECT("'Stammdaten - Schwimmer'!F"&(AC18+3))+INDIRECT("'Stammdaten - Schwimmer'!F"&(AD18+3))+INDIRECT("'Stammdaten - Schwimmer'!F"&(AE18+3))+INDIRECT("'Stammdaten - Schwimmer'!F"&(AF18+3))+INDIRECT("'Stammdaten - Schwimmer'!F"&(AG18+3)) -> 0 | G18: =E18*F18 -> 0 | H18: =IF(D18>0,E18/D18,) -> 0 | I18: 101 | J18: 101 | K18: 101 | L18: 101 | M18: 101 | N18: 101 | O18: 101 | P18: 101 | Q18: 101 | R18: 101 | S18: 101 | T18: 101 | U18: 101 | V18: 101 | W18: 101 | X18: 101 | Y18: 101 | Z18: 101 | AA18: 101 | AB18: 101 | AC18: 101 | AD18: 101 | AE18: 101 | AF18: 101 | AG18: 101 | AH18: 101 | AI18: 101 | AJ18: 101 | AK18: 101 | AL18: 101 | AM18: 101 | AN18: 101
A19: 516 | D19: =COUNTIFS(I19:AQ19,">0",I19:AQ19,"<101") -> 0 | E19: =INDIRECT("'Stammdaten - Schwimmer'!F"&(I19+3))+INDIRECT("'Stammdaten - Schwimmer'!F"&(J19+3))+INDIRECT("'Stammdaten - Schwimmer'!F"&(K19+3))+INDIRECT("'Stammdaten - Schwimmer'!F"&(L19+3))+INDIRECT("'Stammdaten - Schwimmer'!F"&(M19+3))+INDIRECT("'Stammdaten - Schwimmer'!F"&(N19+3))+INDIRECT("'Stammdaten - Schwimmer'!F"&O19+3)+INDIRECT("'Stammdaten - Schwimmer'!F"&(P19+3))+INDIRECT("'Stammdaten - Schwimmer'!F"&(Q19+3))+INDIRECT("'Stammdaten - Schwimmer'!F"&(R19+3))+INDIRECT("'Stammdaten - Schwimmer'!F"&(S19+3))+INDIRECT("'Stammdaten - Schwimmer'!F"&(T19+3))+INDIRECT("'Stammdaten - Schwimmer'!F"&(U19+3))+INDIRECT("'Stammdaten - Schwimmer'!F"&(V19+3))+INDIRECT("'Stammdaten - Schwimmer'!F"&(W19+3))+INDIRECT("'Stammdaten - Schwimmer'!F"&(X19+3))+INDIRECT("'Stammdaten - Schwimmer'!F"&(Y19+3))+INDIRECT("'Stammdaten - Schwimmer'!F"&(Z19+3))+INDIRECT("'Stammdaten - Schwimmer'!F"&(AA19+3))+INDIRECT("'Stammdaten - Schwimmer'!F"&(AB19+3))+INDIRECT("'Stammdaten - Schwimmer'!F"&(AC19+3))+INDIRECT("'Stammdaten - Schwimmer'!F"&(AD19+3))+INDIRECT("'Stammdaten - Schwimmer'!F"&(AE19+3))+INDIRECT("'Stammdaten - Schwimmer'!F"&(AF19+3))+INDIRECT("'Stammdaten - Schwimmer'!F"&(AG19+3)) -> 0 | G19: =E19*F19 -> 0 | H19: =IF(D19>0,E19/D19,) -> 0 | I19: 101 | J19: 101 | K19: 101 | L19: 101 | M19: 101 | N19: 101 | O19: 101 | P19: 101 | Q19: 101 | R19: 101 | S19: 101 | T19: 101 | U19: 101 | V19: 101 | W19: 101 | X19: 101 | Y19: 101 | Z19: 101 | AA19: 101 | AB19: 101 | AC19: 101 | AD19: 101 | AE19: 101 | AF19: 101 | AG19: 101 | AH19: 101 | AI19: 101 | AJ19: 101 | AK19: 101 | AL19: 101 | AM19: 101 | AN19: 101
A20: 517 | D20: =COUNTIFS(I20:AQ20,">0",I20:AQ20,"<101") -> 0 | E20: =INDIRECT("'Stammdaten - Schwimmer'!F"&(I20+3))+INDIRECT("'Stammdaten - Schwimmer'!F"&(J20+3))+INDIRECT("'Stammdaten - Schwimmer'!F"&(K20+3))+INDIRECT("'Stammdaten - Schwimmer'!F"&(L20+3))+INDIRECT("'Stammdaten - Schwimmer'!F"&(M20+3))+INDIRECT("'Stammdaten - Schwimmer'!F"&(N20+3))+INDIRECT("'Stammdaten - Schwimmer'!F"&O20+3)+INDIRECT("'Stammdaten - Schwimmer'!F"&(P20+3))+INDIRECT("'Stammdaten - Schwimmer'!F"&(Q20+3))+INDIRECT("'Stammdaten - Schwimmer'!F"&(R20+3))+INDIRECT("'Stammdaten - Schwimmer'!F"&(S20+3))+INDIRECT("'Stammdaten - Schwimmer'!F"&(T20+3))+INDIRECT("'Stammdaten - Schwimmer'!F"&(U20+3))+INDIRECT("'Stammdaten - Schwimmer'!F"&(V20+3))+INDIRECT("'Stammdaten - Schwimmer'!F"&(W20+3))+INDIRECT("'Stammdaten - Schwimmer'!F"&(X20+3))+INDIRECT("'Stammdaten - Schwimmer'!F"&(Y20+3))+INDIRECT("'Stammdaten - Schwimmer'!F"&(Z20+3))+INDIRECT("'Stammdaten - Schwimmer'!F"&(AA20+3))+INDIRECT("'Stammdaten - Schwimmer'!F"&(AB20+3))+INDIRECT("'Stammdaten - Schwimmer'!F"&(AC20+3))+INDIRECT("'Stammdaten - Schwimmer'!F"&(AD20+3))+INDIRECT("'Stammdaten - Schwimmer'!F"&(AE20+3))+INDIRECT("'Stammdaten - Schwimmer'!F"&(AF20+3))+INDIRECT("'Stammdaten - Schwimmer'!F"&(AG20+3)) -> 0 | G20: =E20*F20 -> 0 | H20: =IF(D20>0,E20/D20,) -> 0 | I20: 101 | J20: 101 | K20: 101 | L20: 101 | M20: 101 | N20: 101 | O20: 101 | P20: 101 | Q20: 101 | R20: 101 | S20: 101 | T20: 101 | U20: 101 | V20: 101 | W20: 101 | X20: 101 | Y20: 101 | Z20: 101 | AA20: 101 | AB20: 101 | AC20: 101 | AD20: 101 | AE20: 101 | AF20: 101 | AG20: 101 | AH20: 101 | AI20: 101 | AJ20: 101 | AK20: 101 | AL20: 101 | AM20: 101 | AN20: 101
