Workbook

Sheet Stammdaten - Schwimmer
A1: Sponsorenschwimmen
A2: Schwimmer (bis zu 100 Schwimmer vorgesehen; Dunkelblau =Testdaten und No-Shows)
A3: Nummer | B3: Name | C3: Vormname | D3: Geburtstag | E3: Mannschaft | F3: Anzahl Bahnen | G3: Sponsor Nr. | H3: Spendehöhe pro Bahn | I3: Max Betrag | J3: Spenden- Ergebnis | K3: Sponsor Nr. | L3: Spendehöhe pro Bahn | M3: Max Betrag | N3: Spenden- Ergebnis | O3: Sponsor Nr. | P3: Spendehöhe pro Bahn | Q3: Max Betrag | R3: Spenden Ergebnis | S3: Sponsor Nr. | T3: Spendehöhe pro Bahn | U3: Max Betrag | V3: Spenden Ergebnis | W3: Sponsor Nr. | X3: Spendehöhe pro Bahn | Y3: Max Betrag | Z3: Spenden Ergebnis
A4: 2 | B4: Grambow | C4: Kerstin | D4: 35065 | E4: 503, 504 | F4: 58 | G4: 1003 | H4: 0.5 | J4: =IF(AND(F4*H4>I4,I4>0),I4, F4*H4) -> 29 | K4: 1004 | L4: 0.5 | N4: =IF(AND(F4*L4>M4,M4>0),M4, F4*L4) -> 29 | O4: 1006 | P4: 0.5 | R4: =IF(AND(F4*P4>Q4,Q4>0),Q4, F4*P4) -> 29 | S4: 1007 | T4: 0.5 | V4: =IF(AND(F4*T4>U4,U4>0),U4, F4*T4) -> 29 | Z4: =IF(AND(F4*X4>Y4,Y4>0),Y4, F4*X4) -> 0
A5: 3 | B5: Gessler | C5: Tom | D5: 42230 | E5: 502 | F5: 24 | G5: 1002 | H5: 0.5 | J5: =IF(AND(F5*H5>I5,I5>0),I5, F5*H5) -> 12 | N5: =IF(AND(F5*L5>M5,M5>0),M5, F5*L5) -> 0 | R5: =IF(AND(F5*P5>Q5,Q5>0),Q5, F5*P5) -> 0 | V5: =IF(AND(F5*T5>U5,U5>0),U5, F5*T5) -> 0 | Z5: =IF(AND(F5*X5>Y5,Y5>0),Y5, F5*X5) -> 0
A6: 4 | B6: Schwenk-Fischer | C6: Eva | D6: 20973 | E6: 505 | F6: 35 | G6: 1005 | H6: 0.5 | J6: =IF(AND(F6*H6>I6,I6>0),I6, F6*H6) -> 17.5 | K6: 1009 | L6: 1 | N6: =IF(AND(F6*L6>M6,M6>0),M6, F6*L6) -> 35 | R6: =IF(AND(F6*P6>Q6,Q6>0),Q6, F6*P6) -> 0 | V6: =IF(AND(F6*T6>U6,U6>0),U6, F6*T6) -> 0 | Z6: =IF(AND(F6*X6>Y6,Y6>0),Y6, F6*X6) -> 0
A7: 5 | B7: Rink | C7: Wiebke | D7: 42566 | E7: 503.505 | F7: 74 | G7: 1003 | H7: 0.5 | J7: =IF(AND(F7*H7>I7,I7>0),I7, F7*H7) -> 37 | K7: 1005 | L7: 0.5 | N7: =IF(AND(F7*L7>M7,M7>0),M7, F7*L7) -> 37 | O7: 1009 | P7: 0.25 | R7: =IF(AND(F7*P7>Q7,Q7>0),Q7, F7*P7) -> 18.5 | V7: =IF(AND(F7*T7>U7,U7>0),U7, F7*T7) -> 0 | Z7: =IF(AND(F7*X7>Y7,Y7>0),Y7, F7*X7) -> 0
A8: 6 | B8: Künsemüller | C8: Viktoria | D8: 40021 | E8: 503 | F8: 70 | G8: 1003 | H8: 0.5 | J8: =IF(AND(F8*H8>I8,I8>0),I8, F8*H8) -> 35 | N8: =IF(AND(F8*L8>M8,M8>0),M8, F8*L8) -> 0 | R8: =IF(AND(F8*P8>Q8,Q8>0),Q8, F8*P8) -> 0 | V8: =IF(AND(F8*T8>U8,U8>0),U8, F8*T8) -> 0 | Z8: =IF(AND(F8*X8>Y8,Y8>0),Y8, F8*X8) -> 0
A9: 7 | B9: Gessler | C9: Anna | D9: 43707 | E9: 502 | F9: 7 | G9: 1002 | H9: 0.5 | J9: =IF(AND(F9*H9>I9,I9>0),I9, F9*H9) -> 3.5 | K9: 1008 | L9: 0.5 | N9: =IF(AND(F9*L9>M9,M9>0),M9, F9*L9) -> 3.5 | R9: =IF(AND(F9*P9>Q9,Q9>0),Q9, F9*P9) -> 0 | V9: =IF(AND(F9*T9>U9,U9>0),U9, F9*T9) -> 0 | Z9: =IF(AND(F9*X9>Y9,Y9>0),Y9, F9*X9) -> 0
A10: 8 | B10: Gessler | C10: Birgit | D10: 29380 | E10: 502 | F10: 42 | G10: 1002 | H10: 0.5 | J10: =IF(AND(F10*H10>I10,I10>0),I10, F10*H10) -> 21 | K10: 1008 | L10: 0.5 | N10: =IF(AND(F10*L10>M10,M10>0),M10, F10*L10) -> 21 | R10: =IF(AND(F10*P10>Q10,Q10>0),Q10, F10*P10) -> 0 | V10: =IF(AND(F10*T10>U10,U10>0),U10, F10*T10) -> 0 | Z10: =IF(AND(F10*X10>Y10,Y10>0),Y10, F10*X10) -> 0
A11: 9 | B11: Künsemüller | C11: Jessika | D11: 40654 | E11: 503 | F11: 74 | G11: 1003 | H11: 0.5 | J11: =IF(AND(F11*H11>I11,I11>0),I11, F11*H11) -> 37 | N11: =IF(AND(F11*L11>M11,M11>0),M11, F11*L11) -> 0 | R11: =IF(AND(F11*P11>Q11,Q11>0),Q11, F11*P11) -> 0 | V11: =IF(AND(F11*T11>U11,U11>0),U11, F11*T11) -> 0 | Z11: =IF(AND(F4*X11>Y11,Y11>0),Y11, F4*X11) -> 0
A12: 10 | B12: Michels | C12: Laurens | D12: 37401 | E12: 502 | F12: 70 | G12: 1002 | H12: 0.5 | J12: =IF(AND(F12*H12>I12,I12>0),I12, F12*H12) -> 35 | K12: 1011 | L12: 0.5 | N12: =IF(AND(F12*L12>M12,M12>0),M12, F12*L12) -> 35 | R12: =IF(AND(F12*P12>Q12,Q12>0),Q12, F12*P12) -> 0 | V12: =IF(AND(F12*T12>U12,U12>0),U12, F12*T12) -> 0 | Z12: =IF(AND(F12*X12>Y12,Y12>0),Y12, F12*X12) -> 0
A13: 11 | B13: Aucher | C13: Neie | D13: 40173 | E13: 502 | F13: 46 | G13: 1002 | H13: 0.5 | J13: =IF(AND(F13*H13>I13,I13>0),I13, F13*H13) -> 23 | K13: 1012 | L13: 1 | N13: =IF(AND(F13*L13>M13,M13>0),M13, F13*L13) -> 46 | O13: 1013 | P13: 2 | R13: =IF(AND(F13*P13>Q13,Q13>0),Q13, F13*P13) -> 92 | V13: =IF(AND(F13*T13>U13,U13>0),U13, F13*T13) -> 0 | Z13: =IF(AND(F13*X13>Y13,Y13>0),Y13, F13*X13) -> 0
A14: 12 | B14: Glass | C14: Helmut | D14: 24492 | E14: 505 | F14: 50 | G14: 1005 | H14: 0.5 | J14: =IF(AND(F14*H14>I14,I14>0),I14, F14*H14) -> 25 | N14: =IF(AND(F14*L14>M14,M14>0),M14, F14*L14) -> 0 | R14: =IF(AND(F14*P14>Q14,Q14>0),Q14, F14*P14) -> 0 | V14: =IF(AND(F14*T14>U14,U14>0),U14, F14*T14) -> 0 | Z14: =IF(AND(F14*X14>Y14,Y14>0),Y14, F14*X14) -> 0
A15: 13 | B15: Bachmann | C15: Anna | D15: 36207 | E15: 503 | F15: 64 | G15: 1003 | H15: 0.5 | J15: =IF(AND(F15*H15>I15,I15>0),I15, F15*H15) -> 32 | N15: =IF(AND(F15*L15>M15,M15>0),M15, F15*L15) -> 0 | R15: =IF(AND(F15*P15>Q15,Q15>0),Q15, F15*P15) -> 0 | V15: =IF(AND(F15*T15>U15,U15>0),U15, F15*T15) -> 0 | Z15: =IF(AND(F15*X15>Y15,Y15>0),Y15, F15*X15) -> 0
A16: 14 | B16: König | C16: Viola | D16: 36605 | E16: 503 | F16: 66 | G16: 1003 | H16: 0.5 | J16: =IF(AND(F16*H16>I16,I16>0),I16, F16*H16) -> 33 | N16: =IF(AND(F16*L16>M16,M16>0),M16, F16*L16) -> 0 | R16: =IF(AND(F16*P16>Q16,Q16>0),Q16, F16*P16) -> 0 | V16: =IF(AND(F16*T16>U16,U16>0),U16, F16*T16) -> 0 | Z16: =IF(AND(F16*X16>Y16,Y16>0),Y16, F16*X16) -> 0
A17: 15 | B17: Kesten | C17: Annabelle | D17: 42053 | E17: 503 | F17: 82 | G17: 1003 | H17: 0.5 | J17: =IF(AND(F17*H17>I17,I17>0),I17, F17*H17) -> 41 | K17: 1014 | L17: 1.5 | N17: =IF(AND(F17*L17>M17,M17>0),M17, F17*L17) -> 123 | O17: 1015 | P17: 0.5 | R17: =IF(AND(F17*P17>Q17,Q17>0),Q17, F17*P17) -> 41 | V17: =IF(AND(F17*T17>U17,U17>0),U17, F17*T17) -> 0 | Z17: =IF(AND(F17*X17>Y17,Y17>0),Y17, F17*X17) -> 0
A18: 16 | B18: Strobel | C18: Liana | D18: 42732 | E18: 503 | F18: 68 | G18: 1003 | H18: 0.5 | J18: =IF(AND(F18*H18>I18,I18>0),I18, F18*H18) -> 34 | N18: =IF(AND(F18*L18>M18,M18>0),M18, F18*L18) -> 0 | R18: =IF(AND(F18*P18>Q18,Q18>0),Q18, F18*P18) -> 0 | V18: =IF(AND(F18*T18>U18,U18>0),U18, F18*T18) -> 0 | Z18: =IF(AND(F18*X18>Y18,Y18>0),Y18, F18*X18) -> 0
A19: 17 | B19: Baur | C19: Seweryn | D19: 33169 | E19: 503.504 | F19: 22 | G19: 1003 | H19: 0.5 | J19: =IF(AND(F19*H19>I19,I19>0),I19, F19*H19) -> 11 | K19: 1004 | L19: 0.5 | N19: =IF(AND(F19*L19>M19,M19>0),M19, F19*L19) -> 11 | R19: =IF(AND(F19*P19>Q19,Q19>0),Q19, F19*P19) -> 0 | V19: =IF(AND(F19*T19>U19,U19>0),U19, F19*T19) -> 0 | Z19: =IF(AND(F19*X19>Y19,Y19>0),Y19, F19*X19) -> 0
A20: 18 | B20: Baur | C20: Amelie | D20: 34191 | E20: 503.504 | F20: 30 | G20: 1003 | H20: 0.5 | J20: =IF(AND(F20*H20>I20,I20>0),I20, F20*H20) -> 15 | K20: 1004 | L20: 0.5 | N20: =IF(AND(F20*L20>M20,M20>0),M20, F20*L20) -> 15 | R20: =IF(AND(F20*P20>Q20,Q20>0),Q20, F20*P20) -> 0 | V20: =IF(AND(F20*T20>U20,U20>0),U20, F20*T20) -> 0 | Z20: =IF(AND(F20*X20>Y20,Y20>0),Y20, F20*X20) -> 0
A21: 19 | B21: Maier | C21: Johannes | D21: 41125 | F21: 90 | G21: 1016 | H21: 1 | I21: 100 | J21: =IF(AND(F21*H21>I21,I21>0),I21, F21*H21) -> 90 | N21: =IF(AND(F21*L21>M21,M21>0),M21, F21*L21) -> 0 | R21: =IF(AND(F21*P21>Q21,Q21>0),Q21, F21*P21) -> 0 | V21: =IF(AND(F21*T21>U21,U21>0),U21, F21*T21) -> 0 | Z21: =IF(AND(F21*X21>Y21,Y21>0),Y21, F21*X21) -> 0
A22: 20 | B22: Winkler | C22: Anette | D22: 22984 | F22: 30 | G22: 1017 | H22: 0.5 | J22: =IF(AND(F22*H22>I22,I22>0),I22, F22*H22) -> 15 | N22: =IF(AND(F22*L22>M22,M22>0),M22, F22*L22) -> 0 | R22: =IF(AND(F22*P22>Q22,Q22>0),Q22, F22*P22) -> 0 | V22: =IF(AND(F22*T22>U22,U22>0),U22, F22*T22) -> 0 | Z22: =IF(AND(F22*X22>Y22,Y22>0),Y22, F22*X22) -> 0
A23: 21 | B23: Laub | C23: Emma | D23: 42017 | F23: 22 | G23: 1018 | H23: 0.5 | J23: =IF(AND(F23*H23>I23,I23>0),I23, F23*H23) -> 11 | N23: =IF(AND(F23*L23>M23,M23>0),M23, F23*L23) -> 0 | R23: =IF(AND(F23*P23>Q23,Q23>0),Q23, F23*P23) -> 0 | V23: =IF(AND(F23*T23>U23,U23>0),U23, F23*T23) -> 0 | Z23: =IF(AND(F23*X23>Y23,Y23>0),Y23, F23*X23) -> 0
A24: 22 | B24: Laub | C24: Jasper | D24: 41553 | F24: 24 | G24: 1018 | H24: 0.5 | J24: =IF(AND(F24*H24>I24,I24>0),I24, F24*H24) -> 12 | N24: =IF(AND(F24*L24>M24,M24>0),M24, F24*L24) -> 0 | R24: =IF(AND(F24*P24>Q24,Q24>0),Q24, F24*P24) -> 0 | V24: =IF(AND(F24*T24>U24,U24>0),U24, F24*T24) -> 0 | Z24: =IF(AND(F24*X24>Y24,Y24>0),Y24, F24*X24) -> 0
A25: 23 | B25: Engel | C25: Katrin | D25: 25956 | E25: 503.504 | F25: 58 | G25: 1003 | H25: 0.5 | J25: =IF(AND(F25*H25>I25,I25>0),I25, F25*H25) -> 29 | K25: 1004 | L25: 0.5 | N25: =IF(AND(F25*L25>M25,M25>0),M25, F25*L25) -> 29 | O25: 1019 | P25: 1 | Q25: 50 | R25: =IF(AND(F25*P25>Q25,Q25>0),Q25, F25*P25) -> 50 | V25: =IF(AND(F25*T25>U25,U25>0),U25, F25*T25) -> 0 | Z25: =IF(AND(F25*X25>Y25,Y25>0),Y25, F25*X25) -> 0
A26: 24 | B26: Engel | C26: Ulrike | D26: 23938 | E26: 503.504 | F26: 60 | G26: 1003 | H26: 0.5 | J26: =IF(AND(F26*H26>I26,I26>0),I26, F26*H26) -> 30 | K26: 1004 | L26: 0.5 | N26: =IF(AND(F26*L26>M26,M26>0),M26, F26*L26) -> 30 | R26: =IF(AND(F26*P26>Q26,Q26>0),Q26, F26*P26) -> 0 | V26: =IF(AND(F26*T26>U26,U26>0),U26, F26*T26) -> 0 | Z26: =IF(AND(F26*X26>Y26,Y26>0),Y26, F26*X26) -> 0
A27: 25 | B27: Sure | C27: Doris | D27: 22857 | E27: 502 | F27: 22 | G27: 1002 | H27: 0.5 | J27: =IF(AND(F27*H27>I27,I27>0),I27, F27*H27) -> 11 | N27: =IF(AND(F27*L27>M27,M27>0),M27, F27*L27) -> 0 | R27: =IF(AND(F27*P27>Q27,Q27>0),Q27, F27*P27) -> 0 | V27: =IF(AND(F27*T27>U27,U27>0),U27, F27*T27) -> 0 | Z27: =IF(AND(F27*X27>Y27,Y27>0),Y27, F27*X27) -> 0
A28: 26 | B28: Bauer | C28: Tim | D28: 35823 | E28: 503 | F28: 50 | G28: 1003 | H28: 0.5 | J28: =IF(AND(F28*H28>I28,I28>0),I28, F28*H28) -> 25 | N28: =IF(AND(F28*L28>M28,M28>0),M28, F28*L28) -> 0 | R28: =IF(AND(F28*P28>Q28,Q28>0),Q28, F28*P28) -> 0 | V28: =IF(AND(F28*T28>U28,U28>0),U28, F28*T28) -> 0 | Z28: =IF(AND(F28*X28>Y28,Y28>0),Y28, F28*X28) -> 0
A29: 27 | B29: Engel | C29: Brigitte | D29: 23066 | F29: 40 | G29: 1020 | H29: 2 | J29: =IF(AND(F29*H29>I29,I29>0),I29, F29*H29) -> 80 | N29: =IF(AND(F29*L29>M29,M29>0),M29, F29*L29) -> 0 | R29: =IF(AND(F29*P29>Q29,Q29>0),Q29, F29*P29) -> 0 | V29: =IF(AND(F29*T29>U29,U29>0),U29, F29*T29) -> 0 | Z29: =IF(AND(F29*X29>Y29,Y29>0),Y29, F29*X29) -> 0
A30: 28 | B30: Zimmermann | C30: Alina | D30: 42146 | F30: 76 | G30: 1021 | H30: 50 | I30: 50 | J30: =IF(AND(F30*H30>I30,I30>0),I30, F30*H30) -> 50 | N30: =IF(AND(F30*L30>M30,M30>0),M30, F30*L30) -> 0 | R30: =IF(AND(F30*P30>Q30,Q30>0),Q30, F30*P30) -> 0 | V30: =IF(AND(F30*T30>U30,U30>0),U30, F30*T30) -> 0 | Z30: =IF(AND(F30*X30>Y30,Y30>0),Y30, F30*X30) -> 0
A31: 29 | B31: Zimmermann | C31: Markus | D31: 28193 | F31: 42 | J31: =IF(AND(F31*H31>I31,I31>0),I31, F31*H31) -> 0 | N31: =IF(AND(F31*L31>M31,M31>0),M31, F31*L31) -> 0 | R31: =IF(AND(F31*P31>Q31,Q31>0),Q31, F31*P31) -> 0 | V31: =IF(AND(F31*T31>U31,U31>0),U31, F31*T31) -> 0 | Z31: =IF(AND(F31*X31>Y31,Y31>0),Y31, F31*X31) -> 0
A32: 30 | B32: Kombacher | C32: Mia | D32: 43635 | E32: 502 | G32: 1002 | H32: 0.5 | J32: =IF(AND(F32*H32>I32,I32>0),I32, F32*H32) -> 0 | K32: 1022 | L32: 0.5 | N32: =IF(AND(F32*L32>M32,M32>0),M32, F32*L32) -> 0 | O32: 1023 | P32: 0.5 | R32: =IF(AND(F32*P32>Q32,Q32>0),Q32, F32*P32) -> 0 | S32: 1024 | T32: 0.5 | V32: =IF(AND(F32*T32>U32,U32>0),U32, F32*T32) -> 0 | Z32: =IF(AND(F32*X32>Y32,Y32>0),Y32, F32*X32) -> 0
A33: 31 | B33: Kombacher | C33: Anja | D33: 30515 | E33: 502 | G33: 1002 | H33: 0.5 | J33: =IF(AND(F33*H33>I33,I33>0),I33, F33*H33) -> 0 | N33: =IF(AND(F33*L33>M33,M33>0),M33, F33*L33) -> 0 | R33: =IF(AND(F33*P33>Q33,Q33>0),Q33, F33*P33) -> 0 | V33: =IF(AND(F33*T33>U33,U33>0),U33, F33*T33) -> 0 | Z33: =IF(AND(F33*X33>Y33,Y33>0),Y33, F33*X33) -> 0
A34: 32 | B34: Kombacher | C34: Lea | D34: 41712 | E34: 502 | F34: 94 | G34: 1002 | H34: 0.5 | J34: =IF(AND(F34*H34>I34,I34>0),I34, F34*H34) -> 47 | K34: 1022 | L34: 0.5 | N34: =IF(AND(F34*L34>M34,M34>0),M34, F34*L34) -> 47 | O34: 1023 | P34: 0.5 | R34: =IF(AND(F34*P34>Q34,Q34>0),Q34, F34*P34) -> 47 | S34: 1024 | T34: 0.5 | V34: =IF(AND(F34*T34>U34,U34>0),U34, F34*T34) -> 47 | Z34: =IF(AND(F34*X34>Y34,Y34>0),Y34, F34*X34) -> 0
A35: 33 | J35: =IF(AND(F35*H35>I35,I35>0),I35, F35*H35) -> 0 | N35: =IF(AND(F35*L35>M35,M35>0),M35, F35*L35) -> 0 | R35: =IF(AND(F35*P35>Q35,Q35>0),Q35, F35*P35) -> 0 | V35: =IF(AND(F35*T35>U35,U35>0),U35, F35*T35) -> 0 | Z35: =IF(AND(F35*X35>Y35,Y35>0),Y35, F35*X35) -> 0
A36: 34 | B36: Kombacher | C36: Sara | D36: 42528 | E36: 502 | F36: 74 | G36: 1002 | H36: 0.5 | J36: =IF(AND(F36*H36>I36,I36>0),I36, F36*H36) -> 37 | K36: 1022 | L36: 0.5 | N36: =IF(AND(F36*L36>M36,M36>0),M36, F36*L36) -> 37 | O36: 1023 | P36: 0.5 | R36: =IF(AND(F36*P36>Q36,Q36>0),Q36, F36*P36) -> 37 | S36: 1024 | T36: 0.5 | V36: =IF(AND(F36*T36>U36,U36>0),U36, F36*T36) -> 37 | Z36: =IF(AND(F36*X36>Y36,Y36>0),Y36, F36*X36) -> 0
A37: 35 | J37: =IF(AND(F37*H37>I37,I37>0),I37, F37*H37) -> 0 | N37: =IF(AND(F37*L37>M37,M37>0),M37, F37*L37) -> 0 | R37: =IF(AND(F37*P37>Q37,Q37>0),Q37, F37*P37) -> 0 | V37: =IF(AND(F37*T37>U37,U37>0),U37, F37*T37) -> 0 | Z37: =IF(AND(F37*X37>Y37,Y37>0),Y37, F37*X37) -> 0
A38: 36 | B38: Hanke | C38: Kerstin | D38: 24695 | E38: 506 | F38: 20 | G38: 1025 | H38: 250 | I38: 240 | J38: =IF(AND(F38*H38>I38,I38>0),I38, F38*H38) -> 240 | N38: =IF(AND(F38*L38>M38,M38>0),M38, F38*L38) -> 0 | R38: =IF(AND(F38*P38>Q38,Q38>0),Q38, F38*P38) -> 0 | V38: =IF(AND(F38*T38>U38,U38>0),U38, F38*T38) -> 0 | Z38: =IF(AND(F38*X38>Y38,Y38>0),Y38, F38*X38) -> 0
A39: 37 | B39: Frank | C39: Konstantin | D39: 34462 | E39: 506 | F39: 30 | G39: 1025 | H39: 250 | I39: 1 | J39: =IF(AND(F39*H39>I39,I39>0),I39, F39*H39) -> 1 | N39: =IF(AND(F39*L39>M39,M39>0),M39, F39*L39) -> 0 | R39: =IF(AND(F39*P39>Q39,Q39>0),Q39, F39*P39) -> 0 | V39: =IF(AND(F39*T39>U39,U39>0),U39, F39*T39) -> 0 | Z39: =IF(AND(F39*X39>Y39,Y39>0),Y39, F39*X39) -> 0
A40: 38 | B40: Laub | C40: Noel | D40: 32001 | E40: 506 | F40: 38 | G40: 1025 | H40: 250 | I40: 1 | J40: =IF(AND(F40*H40>I40,I40>0),I40, F40*H40) -> 1 | N40: =IF(AND(F40*L40>M40,M40>0),M40, F40*L40) -> 0 | R40: =IF(AND(F40*P40>Q40,Q40>0),Q40, F40*P40) -> 0 | V40: =IF(AND(F40*T40>U40,U40>0),U40, F40*T40) -> 0 | Z40: =IF(AND(F40*X40>Y40,Y40>0),Y40, F40*X40) -> 0
...

Sheet Tabelle1
A1: Jungstes Kind | K1: =#REF! -> #REF! | L1: =#REF! -> #REF! | M1: =#REF! -> #REF! | N1: =#REF! -> #REF! | O1: =#REF! -> #REF! | P1: =#REF! -> #REF! | Q1: 50 | R1: =P1*Q1 -> #REF!
A2: ='Stammdaten - Schwimmer'!A3 -> Nummer | B2: ='Stammdaten - Schwimmer'!B3 -> Name | C2: ='Stammdaten - Schwimmer'!C3 -> Vormname | D2: ='Stammdaten - Schwimmer'!D3 -> Geburtstag | E2: ='Stammdaten - Schwimmer'!E3 -> Mannschaft | F2: ='Stammdaten - Schwimmer'!F3 -> Anzahl Bahnen | K2: ='Stammdaten - Schwimmer'!A4 -> 2 | L2: ='stammdaten - schwimmer'!#ref! -> #VALUE! | M2: ='stammdaten - schwimmer'!#ref! -> #VALUE! | N2: ='stammdaten - schwimmer'!#ref! -> #VALUE! | O2: ='stammdaten - schwimmer'!#ref! -> #VALUE! | P2: ='stammdaten - schwimmer'!#ref! -> #VALUE! | Q2: 25 | R2: =P2*Q2 -> #VALUE!
A3: ='Stammdaten - Schwimmer'!A4 -> 2 | B3: ='Stammdaten - Schwimmer'!B4 -> Grambow | C3: ='Stammdaten - Schwimmer'!C4 -> Kerstin | D3: ='Stammdaten - Schwimmer'!D4 -> 35065 | E3: ='Stammdaten - Schwimmer'!E4 -> 503, 504 | F3: ='Stammdaten - Schwimmer'!F4 -> 58 | K3: ='Stammdaten - Schwimmer'!A5 -> 3 | L3: ='Stammdaten - Schwimmer'!B5 -> Gessler | M3: ='Stammdaten - Schwimmer'!C5 -> Tom | N3: ='Stammdaten - Schwimmer'!D5 -> 42230 | O3: ='Stammdaten - Schwimmer'!E5 -> 502 | P3: ='Stammdaten - Schwimmer'!F5 -> 24 | Q3: 25 | R3: =P3*Q3 -> 600
A4: ='Stammdaten - Schwimmer'!A11 -> 9 | B4: ='Stammdaten - Schwimmer'!B11 -> Künsemüller | C4: ='Stammdaten - Schwimmer'!C11 -> Jessika | D4: ='Stammdaten - Schwimmer'!D11 -> 40654 | E4: ='Stammdaten - Schwimmer'!E11 -> 503 | F4: ='Stammdaten - Schwimmer'!F11 -> 74 | K4: ='Stammdaten - Schwimmer'!A6 -> 4 | L4: ='Stammdaten - Schwimmer'!B6 -> Schwenk-Fischer | M4: ='Stammdaten - Schwimmer'!C6 -> Eva | N4: ='Stammdaten - Schwimmer'!D6 -> 20973 | O4: ='Stammdaten - Schwimmer'!E6 -> 505 | P4: ='Stammdaten - Schwimmer'!F6 -> 35 | Q4: 50 | R4: =P4*Q4 -> 1750
A5: ='stammdaten - schwimmer'!#ref! -> #VALUE! | B5: ='stammdaten - schwimmer'!#ref! -> #VALUE! | C5: ='stammdaten - schwimmer'!#ref! -> #VALUE! | D5: ='stammdaten - schwimmer'!#ref! -> #VALUE! | E5: ='stammdaten - schwimmer'!#ref! -> #VALUE! | K5: ='Stammdaten - Schwimmer'!A7 -> 5 | L5: ='Stammdaten - Schwimmer'!B7 -> Rink | M5: ='Stammdaten - Schwimmer'!C7 -> Wiebke | N5: ='Stammdaten - Schwimmer'!D7 -> 42566 | O5: ='Stammdaten - Schwimmer'!E7 -> 503.505 | P5: ='Stammdaten - Schwimmer'!F7 -> 74 | Q5: 25 | R5: =P5*Q5 -> 1850
A6: ='stammdaten - schwimmer'!#ref! -> #VALUE! | B6: ='stammdaten - schwimmer'!#ref! -> #VALUE! | C6: ='stammdaten - schwimmer'!#ref! -> #VALUE! | D6: ='stammdaten - schwimmer'!#ref! -> #VALUE! | E6: ='stammdaten - schwimmer'!#ref! -> #VALUE! | K6: ='Stammdaten - Schwimmer'!A8 -> 6 | L6: ='Stammdaten - Schwimmer'!B8 -> Künsemüller | M6: ='Stammdaten - Schwimmer'!C8 -> Viktoria | N6: ='Stammdaten - Schwimmer'!D8 -> 40021 | O6: ='Stammdaten - Schwimmer'!E8 -> 503 | P6: ='Stammdaten - Schwimmer'!F8 -> 70 | Q6: 50 | R6: =P6*Q6 -> 3500
A7: ='Stammdaten - Schwimmer'!A9 -> 7 | B7: ='Stammdaten - Schwimmer'!B9 -> Gessler | C7: ='Stammdaten - Schwimmer'!C9 -> Anna | D7: ='Stammdaten - Schwimmer'!D9 -> 43707 | E7: ='Stammdaten - Schwimmer'!E9 -> 502 | F7: ='Stammdaten - Schwimmer'!F9 -> 7 | K7: ='Stammdaten - Schwimmer'!A9 -> 7 | L7: ='Stammdaten - Schwimmer'!B9 -> Gessler | M7: ='Stammdaten - Schwimmer'!C9 -> Anna | N7: ='Stammdaten - Schwimmer'!D9 -> 43707 | O7: ='Stammdaten - Schwimmer'!E9 -> 502 | P7: ='Stammdaten - Schwimmer'!F9 -> 7 | Q7: 50 | R7: =P7*Q7 -> 350
A8: ='Stammdaten - Schwimmer'!A32 -> 30 | B8: ='Stammdaten - Schwimmer'!B32 -> Kombacher | C8: ='Stammdaten - Schwimmer'!C32 -> Mia | D8: ='Stammdaten - Schwimmer'!D32 -> 43635 | E8: ='Stammdaten - Schwimmer'!E32 -> 502 | F8: ='Stammdaten - Schwimmer'!F32 -> 0 | K8: ='Stammdaten - Schwimmer'!A10 -> 8 | L8: ='Stammdaten - Schwimmer'!B10 -> Gessler | M8: ='Stammdaten - Schwimmer'!C10 -> Birgit | N8: ='Stammdaten - Schwimmer'!D10 -> 29380 | O8: ='Stammdaten - Schwimmer'!E10 -> 502 | P8: ='Stammdaten - Schwimmer'!F10 -> 42 | Q8: 50 | R8: =P8*Q8 -> 2100
A9: ='Stammdaten - Schwimmer'!A18 -> 16 | B9: ='Stammdaten - Schwimmer'!B18 -> Strobel | C9: ='Stammdaten - Schwimmer'!C18 -> Liana | D9: ='Stammdaten - Schwimmer'!D18 -> 42732 | E9: ='Stammdaten - Schwimmer'!E18 -> 503 | F9: ='Stammdaten - Schwimmer'!F18 -> 68 | K9: ='Stammdaten - Schwimmer'!A11 -> 9 | L9: ='Stammdaten - Schwimmer'!B4 -> Grambow | M9: ='Stammdaten - Schwimmer'!C4 -> Kerstin | N9: ='Stammdaten - Schwimmer'!D4 -> 35065 | O9: ='Stammdaten - Schwimmer'!E4 -> 503, 504 | P9: ='Stammdaten - Schwimmer'!F4 -> 58 | Q9: 50 | R9: =P9*Q9 -> 2900
A10: ='Stammdaten - Schwimmer'!A53 -> 51 | B10: ='Stammdaten - Schwimmer'!B53 -> Warga | C10: ='Stammdaten - Schwimmer'!C53 -> Eva | D10: ='Stammdaten - Schwimmer'!D53 -> 42629 | E10: ='Stammdaten - Schwimmer'!E53 -> 507 | F10: ='Stammdaten - Schwimmer'!F53 -> 108 | K10: ='Stammdaten - Schwimmer'!A12 -> 10 | L10: ='Stammdaten - Schwimmer'!B12 -> Michels | M10: ='Stammdaten - Schwimmer'!C12 -> Laurens | N10: ='Stammdaten - Schwimmer'!D12 -> 37401 | O10: ='Stammdaten - Schwimmer'!E12 -> 502 | P10: ='Stammdaten - Schwimmer'!F12 -> 70 | Q10: 50 | R10: =P10*Q10 -> 3500
A11: ='Stammdaten - Schwimmer'!A62 -> 60 | B11: ='Stammdaten - Schwimmer'!B62 -> Göpel | C11: ='Stammdaten - Schwimmer'!C62 -> Norah | D11: ='Stammdaten - Schwimmer'!D62 -> 42602 | E11: ='Stammdaten - Schwimmer'!E62 -> 502 | F11: ='Stammdaten - Schwimmer'!F62 -> 74 | K11: ='Stammdaten - Schwimmer'!A13 -> 11 | L11: ='Stammdaten - Schwimmer'!B13 -> Aucher | M11: ='Stammdaten - Schwimmer'!C13 -> Neie | N11: ='Stammdaten - Schwimmer'!D13 -> 40173 | O11: ='Stammdaten - Schwimmer'!E13 -> 502 | P11: ='Stammdaten - Schwimmer'!F13 -> 46 | Q11: 50 | R11: =P11*Q11 -> 2300
A12: ='Stammdaten - Schwimmer'!A7 -> 5 | B12: ='Stammdaten - Schwimmer'!B7 -> Rink | C12: ='Stammdaten - Schwimmer'!C7 -> Wiebke | D12: ='Stammdaten - Schwimmer'!D7 -> 42566 | E12: ='Stammdaten - Schwimmer'!E7 -> 503.505 | F12: ='Stammdaten - Schwimmer'!F7 -> 74 | K12: ='Stammdaten - Schwimmer'!A14 -> 12 | L12: ='Stammdaten - Schwimmer'!B14 -> Glass | M12: ='Stammdaten - Schwimmer'!C14 -> Helmut | N12: ='Stammdaten - Schwimmer'!D14 -> 24492 | O12: ='Stammdaten - Schwimmer'!E14 -> 505 | P12: ='Stammdaten - Schwimmer'!F14 -> 50 | Q12: 50 | R12: =P12*Q12 -> 2500
A13: ='Stammdaten - Schwimmer'!A36 -> 34 | B13: ='Stammdaten - Schwimmer'!B36 -> Kombacher | C13: ='Stammdaten - Schwimmer'!C36 -> Sara | D13: ='Stammdaten - Schwimmer'!D36 -> 42528 | E13: ='Stammdaten - Schwimmer'!E36 -> 502 | F13: ='Stammdaten - Schwimmer'!F36 -> 74 | K13: ='Stammdaten - Schwimmer'!A15 -> 13 | L13: ='Stammdaten - Schwimmer'!B15 -> Bachmann | M13: ='Stammdaten - Schwimmer'!C15 -> Anna | N13: ='Stammdaten - Schwimmer'!D15 -> 36207 | O13: ='Stammdaten - Schwimmer'!E15 -> 503 | P13: ='Stammdaten - Schwimmer'!F15 -> 64 | Q13: 50 | R13: =P13*Q13 -> 3200
A14: ='Stammdaten - Schwimmer'!A59 -> 57 | B14: ='Stammdaten - Schwimmer'!B59 -> Hartmann | C14: ='Stammdaten - Schwimmer'!C59 -> Hanna | D14: ='Stammdaten - Schwimmer'!D59 -> 42300 | E14: ='Stammdaten - Schwimmer'!E59 -> 0 | F14: ='Stammdaten - Schwimmer'!F59 -> 26 | K14: ='Stammdaten - Schwimmer'!A16 -> 14 | L14: ='Stammdaten - Schwimmer'!B16 -> König | M14: ='Stammdaten - Schwimmer'!C16 -> Viola | N14: ='Stammdaten - Schwimmer'!D16 -> 36605 | O14: ='Stammdaten - Schwimmer'!E16 -> 503 | P14: ='Stammdaten - Schwimmer'!F16 -> 66 | Q14: 25 | R14: =P14*Q14 -> 1650
A15: ='Stammdaten - Schwimmer'!A61 -> 59 | B15: ='Stammdaten - Schwimmer'!B61 -> Schmid | C15: ='Stammdaten - Schwimmer'!C61 -> Jakob | D15: ='Stammdaten - Schwimmer'!D61 -> 42251 | E15: ='Stammdaten - Schwimmer'!E61 -> 502 | F15: ='Stammdaten - Schwimmer'!F61 -> 94 | K15: ='Stammdaten - Schwimmer'!A17 -> 15 | L15: ='Stammdaten - Schwimmer'!B17 -> Kesten | M15: ='Stammdaten - Schwimmer'!C17 -> Annabelle | N15: ='Stammdaten - Schwimmer'!D17 -> 42053 | O15: ='Stammdaten - Schwimmer'!E17 -> 503 | P15: ='Stammdaten - Schwimmer'!F17 -> 82 | Q15: 25 | R15: =P15*Q15 -> 2050
A16: ='Stammdaten - Schwimmer'!A5 -> 3 | B16: ='Stammdaten - Schwimmer'!B5 -> Gessler | C16: ='Stammdaten - Schwimmer'!C5 -> Tom | D16: ='Stammdaten - Schwimmer'!D5 -> 42230 | E16: ='Stammdaten - Schwimmer'!E5 -> 502 | F16: ='Stammdaten - Schwimmer'!F5 -> 24 | K16: ='Stammdaten - Schwimmer'!A18 -> 16 | L16: ='Stammdaten - Schwimmer'!B18 -> Strobel | M16: ='Stammdaten - Schwimmer'!C18 -> Liana | N16: ='Stammdaten - Schwimmer'!D18 -> 42732 | O16: ='Stammdaten - Schwimmer'!E18 -> 503 | P16: ='Stammdaten - Schwimmer'!F18 -> 68 | Q16: 50 | R16: =P16*Q16 -> 3400
A17: ='Stammdaten - Schwimmer'!A30 -> 28 | B17: ='Stammdaten - Schwimmer'!B30 -> Zimmermann | C17: ='Stammdaten - Schwimmer'!C30 -> Alina | D17: ='Stammdaten - Schwimmer'!D30 -> 42146 | E17: ='Stammdaten - Schwimmer'!E30 -> 0 | F17: ='Stammdaten - Schwimmer'!F30 -> 76 | K17: ='Stammdaten - Schwimmer'!A19 -> 17 | L17: ='Stammdaten - Schwimmer'!B19 -> Baur | M17: ='Stammdaten - Schwimmer'!C19 -> Seweryn | N17: ='Stammdaten - Schwimmer'!D19 -> 33169 | O17: ='Stammdaten - Schwimmer'!E19 -> 503.504 | P17: ='Stammdaten - Schwimmer'!F19 -> 22 | Q17: 25 | R17: =P17*Q17 -> 550
A18: ='Stammdaten - Schwimmer'!A64 -> 62 | B18: ='Stammdaten - Schwimmer'!B64 -> Zhou | C18: ='Stammdaten - Schwimmer'!C64 -> Robin | D18: ='Stammdaten - Schwimmer'!D64 -> 42116 | E18: ='Stammdaten - Schwimmer'!E64 -> 503 | F18: ='Stammdaten - Schwimmer'!F64 -> 80 | K18: ='Stammdaten - Schwimmer'!A20 -> 18 | L18: ='Stammdaten - Schwimmer'!B20 -> Baur | M18: ='Stammdaten - Schwimmer'!C20 -> Amelie | N18: ='Stammdaten - Schwimmer'!D20 -> 34191 | O18: ='Stammdaten - Schwimmer'!E20 -> 503.504 | P18: ='Stammdaten - Schwimmer'!F20 -> 30 | Q18: 25 | R18: =P18*Q18 -> 750
A19: ='Stammdaten - Schwimmer'!A17 -> 15 | B19: ='Stammdaten - Schwimmer'!B17 -> Kesten | C19: ='Stammdaten - Schwimmer'!C17 -> Annabelle | D19: ='Stammdaten - Schwimmer'!D17 -> 42053 | E19: ='Stammdaten - Schwimmer'!E17 -> 503 | F19: ='Stammdaten - Schwimmer'!F17 -> 82 | K19: ='Stammdaten - Schwimmer'!A21 -> 19 | L19: ='Stammdaten - Schwimmer'!B21 -> Maier | M19: ='Stammdaten - Schwimmer'!C21 -> Johannes | N19: ='Stammdaten - Schwimmer'!D21 -> 41125 | O19: ='Stammdaten - Schwimmer'!E21 -> 0 | P19: ='Stammdaten - Schwimmer'!F21 -> 90 | Q19: 25 | R19: =P19*Q19 -> 2250
A20: ='Stammdaten - Schwimmer'!A50 -> 48 | B20: ='Stammdaten - Schwimmer'!B50 -> Holste | C20: ='Stammdaten - Schwimmer'!C50 -> Oscar | D20: ='Stammdaten - Schwimmer'!D50 -> 42027 | E20: ='Stammdaten - Schwimmer'!E50 -> 503 | F20: ='Stammdaten - Schwimmer'!F50 -> 122 | K20: ='Stammdaten - Schwimmer'!A22 -> 20 | L20: ='Stammdaten - Schwimmer'!B22 -> Winkler | M20: ='Stammdaten - Schwimmer'!C22 -> Anette | N20: ='Stammdaten - Schwimmer'!D22 -> 22984 | O20: ='Stammdaten - Schwimmer'!E22 -> 0 | P20: ='Stammdaten - Schwimmer'!F22 -> 30 | Q20: 50 | R20: =P20*Q20 -> 1500
A21: ='Stammdaten - Schwimmer'!A23 -> 21 | B21: ='Stammdaten - Schwimmer'!B23 -> Laub | C21: ='Stammdaten - Schwimmer'!C23 -> Emma | D21: ='Stammdaten - Schwimmer'!D23 -> 42017 | E21: ='Stammdaten - Schwimmer'!E23 -> 0 | F21: ='Stammdaten - Schwimmer'!F23 -> 22 | K21: ='Stammdaten - Schwimmer'!A23 -> 21 | L21: ='Stammdaten - Schwimmer'!B23 -> Laub | M21: ='Stammdaten - Schwimmer'!C23 -> Emma | N21: ='Stammdaten - Schwimmer'!D23 -> 42017 | O21: ='Stammdaten - Schwimmer'!E23 -> 0 | P21: ='Stammdaten - Schwimmer'!F23 -> 22 | Q21: 50 | R21: =P21*Q21 -> 1100
A22: ='Stammdaten - Schwimmer'!A65 -> 63 | B22: ='Stammdaten - Schwimmer'!B65 -> Buuck | C22: ='Stammdaten - Schwimmer'!C65 -> Jan-Alexander | D22: ='Stammdaten - Schwimmer'!D65 -> 41849 | E22: ='Stammdaten - Schwimmer'!E65 -> 502 | F22: ='Stammdaten - Schwimmer'!F65 -> 40 | K22: ='Stammdaten - Schwimmer'!A24 -> 22 | L22: ='Stammdaten - Schwimmer'!B24 -> Laub | M22: ='Stammdaten - Schwimmer'!C24 -> Jasper | N22: ='Stammdaten - Schwimmer'!D24 -> 41553 | O22: ='Stammdaten - Schwimmer'!E24 -> 0 | P22: ='Stammdaten - Schwimmer'!F24 -> 24 | Q22: 50 | R22: =P22*Q22 -> 1200
A23: ='Stammdaten - Schwimmer'!A34 -> 32 | B23: ='Stammdaten - Schwimmer'!B34 -> Kombacher | C23: ='Stammdaten - Schwimmer'!C34 -> Lea | D23: ='Stammdaten - Schwimmer'!D34 -> 41712 | E23: ='Stammdaten - Schwimmer'!E34 -> 502 | F23: ='Stammdaten - Schwimmer'!F34 -> 94 | K23: ='Stammdaten - Schwimmer'!A25 -> 23 | L23: ='Stammdaten - Schwimmer'!B25 -> Engel | M23: ='Stammdaten - Schwimmer'!C25 -> Katrin | N23: ='Stammdaten - Schwimmer'!D25 -> 25956 | O23: ='Stammdaten - Schwimmer'!E25 -> 503.504 | P23: ='Stammdaten - Schwimmer'!F25 -> 58 | Q23: 25 | R23: =P23*Q23 -> 1450
A24: ='Stammdaten - Schwimmer'!A24 -> 22 | B24: ='Stammdaten - Schwimmer'!B24 -> Laub | C24: ='Stammdaten - Schwimmer'!C24 -> Jasper | D24: ='Stammdaten - Schwimmer'!D24 -> 41553 | E24: ='Stammdaten - Schwimmer'!E24 -> 0 | F24: ='Stammdaten - Schwimmer'!F24 -> 24 | K24: ='Stammdaten - Schwimmer'!A26 -> 24 | L24: ='Stammdaten - Schwimmer'!B26 -> Engel | M24: ='Stammdaten - Schwimmer'!C26 -> Ulrike | N24: ='Stammdaten - Schwimmer'!D26 -> 23938 | O24: ='Stammdaten - Schwimmer'!E26 -> 503.504 | P24: ='Stammdaten - Schwimmer'!F26 -> 60 | Q24: 25 | R24: =P24*Q24 -> 1500
A25: ='Stammdaten - Schwimmer'!A57 -> 55 | B25: ='Stammdaten - Schwimmer'!B57 -> Veit | C25: ='Stammdaten - Schwimmer'!C57 -> Dorothea | D25: ='Stammdaten - Schwimmer'!D57 -> 41475 | E25: ='Stammdaten - Schwimmer'!E57 -> 503 | F25: ='Stammdaten - Schwimmer'!F57 -> 32 | K25: ='Stammdaten - Schwimmer'!A27 -> 25 | L25: ='Stammdaten - Schwimmer'!B27 -> Sure | M25: ='Stammdaten - Schwimmer'!C27 -> Doris | N25: ='Stammdaten - Schwimmer'!D27 -> 22857 | O25: ='Stammdaten - Schwimmer'!E27 -> 502 | P25: ='Stammdaten - Schwimmer'!F27 -> 22 | Q25: 25 | R25: =P25*Q25 -> 550
A26: ='Stammdaten - Schwimmer'!A51 -> 49 | B26: ='Stammdaten - Schwimmer'!B51 -> Holste | C26: ='Stammdaten - Schwimmer'!C51 -> Lotte | D26: ='Stammdaten - Schwimmer'!D51 -> 41408 | E26: ='Stammdaten - Schwimmer'!E51 -> 503 | F26: ='Stammdaten - Schwimmer'!F51 -> 120 | K26: ='Stammdaten - Schwimmer'!A28 -> 26 | L26: ='Stammdaten - Schwimmer'!B28 -> Bauer | M26: ='Stammdaten - Schwimmer'!C28 -> Tim | N26: ='Stammdaten - Schwimmer'!D28 -> 35823 | O26: ='Stammdaten - Schwimmer'!E28 -> 503 | P26: ='Stammdaten - Schwimmer'!F28 -> 50 | Q26: 25 | R26: =P26*Q26 -> 1250
A27: ='Stammdaten - Schwimmer'!A60 -> 58 | B27: ='Stammdaten - Schwimmer'!B60 -> Schmid | C27: ='Stammdaten - Schwimmer'!C60 -> Hannes | D27: ='Stammdaten - Schwimmer'!D60 -> 41282 | E27: ='Stammdaten - Schwimmer'!E60 -> 502 | F27: ='Stammdaten - Schwimmer'!F60 -> 108 | K27: ='Stammdaten - Schwimmer'!A29 -> 27 | L27: ='Stammdaten - Schwimmer'!B29 -> Engel | M27: ='Stammdaten - Schwimmer'!C29 -> Brigitte | N27: ='Stammdaten - Schwimmer'!D29 -> 23066 | O27: ='Stammdaten - Schwimmer'!E29 -> 0 | P27: ='Stammdaten - Schwimmer'!F29 -> 40 | Q27: 25 | R27: =P27*Q27 -> 1000
A28: ='Stammdaten - Schwimmer'!A21 -> 19 | B28: ='Stammdaten - Schwimmer'!B21 -> Maier | C28: ='Stammdaten - Schwimmer'!C21 -> Johannes | D28: ='Stammdaten - Schwimmer'!D21 -> 41125 | E28: ='Stammdaten - Schwimmer'!E21 -> 0 | F28: ='Stammdaten - Schwimmer'!F21 -> 90 | K28: ='Stammdaten - Schwimmer'!A30 -> 28 | L28: ='Stammdaten - Schwimmer'!B30 -> Zimmermann | M28: ='Stammdaten - Schwimmer'!C30 -> Alina | N28: ='Stammdaten - Schwimmer'!D30 -> 42146 | O28: ='Stammdaten - Schwimmer'!E30 -> 0 | P28: ='Stammdaten - Schwimmer'!F30 -> 76 | Q28: 25 | R28: =P28*Q28 -> 1900
A29: ='Stammdaten - Schwimmer'!A58 -> 56 | B29: ='Stammdaten - Schwimmer'!B58 -> Heineke | C29: ='Stammdaten - Schwimmer'!C58 -> Jana | D29: ='Stammdaten - Schwimmer'!D58 -> 40445 | E29: ='Stammdaten - Schwimmer'!E58 -> 503 | F29: ='Stammdaten - Schwimmer'!F58 -> 40 | K29: ='Stammdaten - Schwimmer'!A31 -> 29 | L29: ='Stammdaten - Schwimmer'!B31 -> Zimmermann | M29: ='Stammdaten - Schwimmer'!C31 -> Markus | N29: ='Stammdaten - Schwimmer'!D31 -> 28193 | O29: ='Stammdaten - Schwimmer'!E31 -> 0 | P29: ='Stammdaten - Schwimmer'!F31 -> 42 | Q29: 25 | R29: =P29*Q29 -> 1050
A30: ='Stammdaten - Schwimmer'!A45 -> 43 | B30: ='Stammdaten - Schwimmer'!B45 -> Fischer | C30: ='Stammdaten - Schwimmer'!C45 -> Luca | D30: ='Stammdaten - Schwimmer'!D45 -> 40369 | E30: ='Stammdaten - Schwimmer'!E45 -> 506 | F30: ='Stammdaten - Schwimmer'!F45 -> 20 | K30: ='Stammdaten - Schwimmer'!A32 -> 30 | L30: ='Stammdaten - Schwimmer'!B32 -> Kombacher | M30: ='Stammdaten - Schwimmer'!C32 -> Mia | N30: ='Stammdaten - Schwimmer'!D32 -> 43635 | O30: ='Stammdaten - Schwimmer'!E32 -> 502 | P30: ='Stammdaten - Schwimmer'!F32 -> 0 | Q30: 50 | R30: =P30*Q30 -> 0
A31: ='Stammdaten - Schwimmer'!A52 -> 50 | B31: ='Stammdaten - Schwimmer'!B52 -> Ludwig | C31: ='Stammdaten - Schwimmer'!C52 -> Mariya | D31: ='Stammdaten - Schwimmer'!D52 -> 40298 | E31: ='Stammdaten - Schwimmer'!E52 -> 502 | F31: ='Stammdaten - Schwimmer'!F52 -> 52 | K31: ='Stammdaten - Schwimmer'!A33 -> 31 | L31: ='Stammdaten - Schwimmer'!B33 -> Kombacher | M31: ='Stammdaten - Schwimmer'!C33 -> Anja | N31: ='Stammdaten - Schwimmer'!D33 -> 30515 | O31: ='Stammdaten - Schwimmer'!E33 -> 502 | P31: ='Stammdaten - Schwimmer'!F33 -> 0 | Q31: 25 | R31: =P31*Q31 -> 0
A32: =#REF! -> #REF! | B32: =#REF! -> #REF! | C32: =#REF! -> #REF! | D32: =#REF! -> #REF! | E32: =#REF! -> #REF! | F32: =#REF! -> #REF! | K32: ='Stammdaten - Schwimmer'!A34 -> 32 | L32: ='Stammdaten - Schwimmer'!B34 -> Kombacher | M32: ='Stammdaten - Schwimmer'!C34 -> Lea | N32: ='Stammdaten - Schwimmer'!D34 -> 41712 | O32: ='Stammdaten - Schwimmer'!E34 -> 502 | P32: ='Stammdaten - Schwimmer'!F34 -> 94 | Q32: 25 | R32: =P32*Q32 -> 2350
A33: ='Stammdaten - Schwimmer'!A13 -> 11 | B33: ='Stammdaten - Schwimmer'!B13 -> Aucher | C33: ='Stammdaten - Schwimmer'!C13 -> Neie | D33: ='Stammdaten - Schwimmer'!D13 -> 40173 | E33: ='Stammdaten - Schwimmer'!E13 -> 502 | F33: ='Stammdaten - Schwimmer'!F13 -> 46 | K33: ='Stammdaten - Schwimmer'!A35 -> 33 | L33: ='Stammdaten - Schwimmer'!B35 -> 0 | M33: ='Stammdaten - Schwimmer'!C35 -> 0 | N33: ='Stammdaten - Schwimmer'!D35 -> 0 | O33: ='Stammdaten - Schwimmer'!E35 -> 0 | P33: ='Stammdaten - Schwimmer'!F35 -> 0 | Q33: 50 | R33: =P33*Q33 -> 0
A34: ='Stammdaten - Schwimmer'!A8 -> 6 | B34: ='Stammdaten - Schwimmer'!B8 -> Künsemüller | C34: ='Stammdaten - Schwimmer'!C8 -> Viktoria | D34: ='Stammdaten - Schwimmer'!D8 -> 40021 | E34: ='Stammdaten - Schwimmer'!E8 -> 503 | F34: ='Stammdaten - Schwimmer'!F8 -> 70 | K34: ='Stammdaten - Schwimmer'!A36 -> 34 | L34: ='Stammdaten - Schwimmer'!B36 -> Kombacher | M34: ='Stammdaten - Schwimmer'!C36 -> Sara | N34: ='Stammdaten - Schwimmer'!D36 -> 42528 | O34: ='Stammdaten - Schwimmer'!E36 -> 502 | P34: ='Stammdaten - Schwimmer'!F36 -> 74 | Q34: 50 | R34: =P34*Q34 -> 3700
A35: ='Stammdaten - Schwimmer'!A55 -> 53 | B35: ='Stammdaten - Schwimmer'!B55 -> Warga | C35: ='Stammdaten - Schwimmer'!C55 -> Paula | D35: ='Stammdaten - Schwimmer'!D55 -> 39823 | E35: ='Stammdaten - Schwimmer'!E55 -> 507 | F35: ='Stammdaten - Schwimmer'!F55 -> 60 | K35: ='Stammdaten - Schwimmer'!A37 -> 35 | L35: ='Stammdaten - Schwimmer'!B37 -> 0 | M35: ='Stammdaten - Schwimmer'!C37 -> 0 | N35: ='Stammdaten - Schwimmer'!D37 -> 0 | O35: ='Stammdaten - Schwimmer'!E37 -> 0 | P35: ='Stammdaten - Schwimmer'!F37 -> 0 | Q35: 25 | R35: =P35*Q35 -> 0
A36: ='Stammdaten - Schwimmer'!A43 -> 41 | B36: ='Stammdaten - Schwimmer'!B43 -> Fischer | C36: ='Stammdaten - Schwimmer'!C43 -> Chiara | D36: ='Stammdaten - Schwimmer'!D43 -> 38846 | E36: ='Stammdaten - Schwimmer'!E43 -> 506 | F36: ='Stammdaten - Schwimmer'!F43 -> 24 | K36: ='Stammdaten - Schwimmer'!A38 -> 36 | L36: ='Stammdaten - Schwimmer'!B38 -> Hanke | M36: ='Stammdaten - Schwimmer'!C38 -> Kerstin | N36: ='Stammdaten - Schwimmer'!D38 -> 24695 | O36: ='Stammdaten - Schwimmer'!E38 -> 506 | P36: ='Stammdaten - Schwimmer'!F38 -> 20 | Q36: 50 | R36: =P36*Q36 -> 1000
A37: ='Stammdaten - Schwimmer'!A71 -> 69 | B37: ='Stammdaten - Schwimmer'!B71 -> Müller | C37: ='Stammdaten - Schwimmer'!C71 -> Nick | D37: ='Stammdaten - Schwimmer'!D71 -> 38183 | E37: ='Stammdaten - Schwimmer'!E71 -> 0 | F37: ='Stammdaten - Schwimmer'!F71 -> 30 | K37: ='Stammdaten - Schwimmer'!A39 -> 37 | L37: ='Stammdaten - Schwimmer'!B39 -> Frank | M37: ='Stammdaten - Schwimmer'!C39 -> Konstantin | N37: ='Stammdaten - Schwimmer'!D39 -> 34462 | O37: ='Stammdaten - Schwimmer'!E39 -> 506 | P37: ='Stammdaten - Schwimmer'!F39 -> 30 | Q37: 50 | R37: =P37*Q37 -> 1500
A38: ='Stammdaten - Schwimmer'!A70 -> 68 | B38: ='Stammdaten - Schwimmer'!B70 -> Michaelis | C38: ='Stammdaten - Schwimmer'!C70 -> Jochen | D38: ='Stammdaten - Schwimmer'!D70 -> 37973 | E38: ='Stammdaten - Schwimmer'!E70 -> 0 | F38: ='Stammdaten - Schwimmer'!F70 -> 30 | K38: ='Stammdaten - Schwimmer'!A40 -> 38 | L38: ='Stammdaten - Schwimmer'!B40 -> Laub | M38: ='Stammdaten - Schwimmer'!C40 -> Noel | N38: ='Stammdaten - Schwimmer'!D40 -> 32001 | O38: ='Stammdaten - Schwimmer'!E40 -> 506 | P38: ='Stammdaten - Schwimmer'!F40 -> 38 | Q38: 50 | R38: =P38*Q38 -> 1900
A39: ='Stammdaten - Schwimmer'!A12 -> 10 | B39: ='Stammdaten - Schwimmer'!B12 -> Michels | C39: ='Stammdaten - Schwimmer'!C12 -> Laurens | D39: ='Stammdaten - Schwimmer'!D12 -> 37401 | E39: ='Stammdaten - Schwimmer'!E12 -> 502 | F39: ='Stammdaten - Schwimmer'!F12 -> 70 | K39: ='Stammdaten - Schwimmer'!A41 -> 39 | L39: ='Stammdaten - Schwimmer'!B41 -> Drensek | M39: ='Stammdaten - Schwimmer'!C41 -> Deborah | N39: ='Stammdaten - Schwimmer'!D41 -> 34356 | O39: ='Stammdaten - Schwimmer'!E41 -> 506 | P39: ='Stammdaten - Schwimmer'!F41 -> 20 | Q39: 50 | R39: =P39*Q39 -> 1000
A40: ='Stammdaten - Schwimmer'!A16 -> 14 | B40: ='Stammdaten - Schwimmer'!B16 -> König | C40: ='Stammdaten - Schwimmer'!C16 -> Viola | D40: ='Stammdaten - Schwimmer'!D16 -> 36605 | E40: ='Stammdaten - Schwimmer'!E16 -> 503 | F40: ='Stammdaten - Schwimmer'!F16 -> 66 | K40: ='Stammdaten - Schwimmer'!A42 -> 40 | L40: ='Stammdaten - Schwimmer'!B42 -> Laub | M40: ='Stammdaten - Schwimmer'!C42 -> Tanja | N40: ='Stammdaten - Schwimmer'!D42 -> 32160 | O40: ='Stammdaten - Schwimmer'!E42 -> 506 | P40: ='Stammdaten - Schwimmer'!F42 -> 20 | Q40: 50 | R40: =P40*Q40 -> 1000
...

Sheet Stammdaten - Sponsoren
A1: Sponsoren (bis zu 100 Sponsoren vorgesehen)
A3: Nummer | B3: Name / Unternehmen | C3: Vorname / Vertreter | D3: Adresse | E3: Max. Betrag | F3: Gesponsorte Schwimmer / Mannschaft | G3: Gesponsorte Schwimmer / Mannschaft | H3: Gesponsorte Schwimmer / Mannschaft | I3: Gesponsorte Schwimmer / Mannschaft | J3: Gesponsorte Schwimmer / Mannschaft | K3: Gesponsorte Schwimmer / Mannschaft | L3: Gesponsorte Schwimmer / Mannschaft | M3: Gesponsorte Schwimmer / Mannschaft | N3: Gesponsorte Schwimmer / Mannschaft
A4: 1001 | B4: Förderverein ETB | C4: Thomas Schmid
A5: 1002 | B5: DLRG OG VAI | C5: Thomas Schmid | D5: Walter-de-Pay Str.; Vaihingen (Enz) | F5: 502 | G5: 3 | H5: 7 | I5: 8 | J5: 10 | K5: 11 | L5: 25 | M5: 30 | N5: 31 | O5: 32 | P5: 34 | Q5: 50 | R5: 58 | S5: 59 | T5: 60 | U5: 61 | V5: 63
A6: 1003 | B6: TVV Schwimmabteilung | C6: Tim Bauer | D6: Walter-de-Pay Str.; 71665 Vaihingen | F6: 503 | G6: 2 | H6: 5 | I6: 6 | J6: 9 | K6: 13 | L6: 14 | M6: 15 | N6: 16 | O6: 17 | P6: 18 | Q6: 23 | R6: 24 | S6: 26 | T6: 47 | U6: 48 | V6: 49 | W6: 55 | X6: 56 | Y6: 62 | Z6: 65
A7: 1004 | B7: Symmetree GmbH | C7: James Hartman | D7: Königstr. 26; 70173 Stuttgart | F7: 504 | G7: 2 | H7: 17 | I7: 18 | J7: 23 | K7: 24 | L7: 65
A8: 1005 | B8: Kanuclub CJD kaltenstein | C8: Michael Fischer | D8: Klaiberstr 7/1 71665 Vaihingen Enz | F8: 505 | H8: 4 | I8: 5 | J8: 12
A9: 1006 | B9: Auto Service Frank Striebel | C9: Frank Striebel | D9: Römerstr 28, 74399 Walheim | F9: 2
A10: 1007 | B10: Grambow | C10: Kerstin | D10: Weidenweg 10 71665 Vaihingen Enz | F10: 2
A11: 1008 | B11: Gessler | C11: Andreas | D11: Wilhelmstr. 20/2 ORI | F11: 3 | H11: 7 | I11: 8
A12: 1009 | B12: Fischer | C12: Michael | D12: Klaiberstr 7/1 71665 Vaihingen Enz | F12: 4 | H12: 5
A13: 1010 | B13: Rink | C13: Bärbel und Björn | D13: Eugen-Eisele-Weg 8 | F13: 5
A14: 1011 | B14: Michels | C14: Laurens | D14: Oberriexinger Weg 90 71665 Vaihingen/Enz | F14: 10
A15: 1012 | B15: Schmid | C15: Günter | D15: Am Heidenstock 5 64807 Dieburg | E15: 100 | F15: 11
A16: 1013 | B16: Auchter | C16: Tonja Holger | D16: August-Lämmle-Str. 35 71735 Eberdingen | E16: 100 | F16: 11
A17: 1014 | B17: Thiele | C17: Stephan | D17: Friedrichstr. 13 71665 Vaihingen | E17: 50 | F17: 15
A18: 1015 | B18: Kesten | C18: Carla | D18: Roßwager Str. 50 71665 Vaihingen | E18: 10 | F18: 15
A19: 1016 | B19: Maier | C19: Heidi | D19: Gerokstr. 8 71665 Vaihinegn | E19: 100 | F19: 19
A20: 1017 | B20: Schaufelberger | C20: Werner | D20: Gertenstr. 35 71735 Eberdingen | F20: 20
A21: 1018 | B21: Hausund Gertenservice | D21: Eichenweg 3 71739 ORI | F21: 21 | G21: 22 | H21: 57
A22: 1019 | B22: Thewett | C22: Thomas Schmid | D22: Lessingstr 1 71735 Eberdingen | E22: 50 | F22: 23
A23: 1020 | B23: Schwertle | C23: Ariane | D23: Römertsr. 28 71665 Vaihingen Enz | F23: 27
A24: 1021 | B24: Zimmermann | C24: Markus | D24: Friedricstr. 25 74372 Sersheim | E24: 50 | F24: 28 | G24: 29
A25: 1022 | B25: Seel | C25: Rita | D25: Dürer Ring 22 74372 Serseim | E25: 50 | F25: 30 | G25: 34 | H25: 32
A26: 1023 | B26: Kombächer | C26: Dagmar | D26: Zur Talwiese24 57334 Bad Laasphe | E26: 50 | F26: 30 | G26: 34 | H26: 32
A27: 1024 | B27: Häcker | C27: Rudi | D27: Jahnstr. 32 74371 sersheim | E27: 50 | F27: 30 | G27: 34 | H27: 32
A28: 1025 | B28: DRK | C28: ortverein Vaihingen Enz | F28: 36 | G28: 37 | H28: 38 | I28: 39 | J28: 40 | K28: 41 | L28: 42 | M28: 43 | N28: 44 | O28: 45 | P28: 46
A29: 1026
A30: 1027
A31: 1028
A32: 1029
A33: 1030
A34: 1031 | B34: Burck | C34: Andreas | D34: Mauerpfefferweg 6 71665 Vaihinegn Enz | E34: 70
A35: 1032 | B35: Maier | C35: Cordula | D35: Mauerpfeferweg 4 71665 Vaihingen Enz
A36: 1033 | B36: Thiele | C36: Stephen | D36: Friedrichstr 13 71665 Vaihinegn Enz
A37: 1034 | B37: Ludwig | C37: Martin | D37: Weizenstr 36 71665 Vaihingn Enz | F37: 50
A38: 1035 | B38: Umminger Veit | C38: Sybille | D38: Gerokstr. 41 71665 vVaihingen Enz | E38: 100
A39: 1036 | B39: Umminger | C39: Irmgard | D39: Edenkobener Str 22 | E39: 40
A40: 1037 | B40: Veith | C40: Martin | D40: Gerokstr. 41 71665 vVaihingen Enz
A41: 1038 | B41: Düsterloh | C41: Anete und Dario | D41: Gothestr. 19/2 71665 Vaihingen Enz
...

Sheet Stammdaten Teams
A1: Team Zusammenstetzungen
A2: (bis zu 25 Schwimmer im Team und bis zu 50 Teams vorgesehen)
A3: Team Nummer | B3: Team Name | C3: Verantwortlicher | D3: Gesamt Mitglieder | E3: Gesamtanzahl Bahnen | F3: Spende pro Bahn | G3: Spenden- Betrag | H3: Bahnen pro Mitglied | I3: Zugehöriger Schwimmer | J3: Zugehöriger Schwimmer | K3: Zugehöriger Schwimmer | L3: Zugehöriger Schwimmer | M3: Zugehöriger Schwimmer | N3: Zugehöriger Schwimmer | O3: Zugehöriger Schwimmer | P3: Zugehöriger Schwimmer | Q3: Zugehöriger Schwimmer | R3: Zugehöriger Schwimmer | S3: Zugehöriger Schwimmer | T3: Zugehöriger Schwimmer | U3: Zugehöriger Schwimmer | V3: Zugehöriger Schwimmer | W3: Zugehöriger Schwimmer | X3: Zugehöriger Schwimmer | Y3: Zugehöriger Schwimmer | Z3: Zugehöriger Schwimmer | AA3: Zugehöriger Schwimmer | AB3: Zugehöriger Schwimmer | AC3: Zugehöriger Schwimmer | AD3: Zugehöriger Schwimmer | AE3: Zugehöriger Schwimmer | AF3: Zugehöriger Schwimmer | AG3: Zugehöriger Schwimmer
A4: 501 | B4: FV ETB | D4: =COUNTIF(I4:AQ4,">0") -> 0 | H4: =IF(D4>0,E4/D4,) -> 0
A5: 502 | B5: DLRG | C5: Thomas Schmid | D5: =COUNTIFS(I5:AQ5,">0",I5:AQ5,"<101") -> 16 | E5: =SUMIF('Stammdaten - Schwimmer'!G$4:G$99,'Stammdaten - Sponsoren'!A5,'Stammdaten - Schwimmer'!F$4:F$99)+SUMIF('Stammdaten - Schwimmer'!K$4:K$99,'Stammdaten - Sponsoren'!A5,'Stammdaten - Schwimmer'!F$4:F$99)+SUMIF('Stammdaten - Schwimmer'!O$4:O$99,'Stammdaten - Sponsoren'!A5,'Stammdaten - Schwimmer'!F$4:F$99)+SUMIF('Stammdaten - Schwimmer'!S$4:S$99,'Stammdaten - Sponsoren'!A5,'Stammdaten - Schwimmer'!F$4:F$99) -> 769 | F5: 0.5 | G5: =E5*F5 -> 384.5 | H5: =IF(D5>0,E5/D5,) -> 48.0625 | I5: 3 | J5: 7 | K5: 8 | L5: 10 | M5: 11 | N5: 25 | O5: 30 | P5: 31 | Q5: 32 | R5: 34 | S5: 50 | T5: 58 | U5: 59 | V5: 60 | W5: 61 | X5: 63 | Y5: 101 | Z5: 101 | AA5: 101 | AB5: 101 | AC5: 101 | AD5: 101 | AE5: 101 | AF5: 101 | AG5: 101 | AH5: 101 | AI5: 101 | AJ5: 101 | AK5: 101 | AL5: 101 | AM5: 101 | AN5: 101 | AO5: 101 | AP5: 101
A6: 503 | B6: TVV Schwimm | C6: Tim Bauer | D6: =COUNTIFS(I6:AQ6,">0",I6:AQ6,"<101") -> 20 | E6: =SUMIF('Stammdaten - Schwimmer'!G$4:G$99,'Stammdaten - Sponsoren'!A6,'Stammdaten - Schwimmer'!F$4:F$99)+SUMIF('Stammdaten - Schwimmer'!K$4:K$99,'Stammdaten - Sponsoren'!A6,'Stammdaten - Schwimmer'!F$4:F$99)+SUMIF('Stammdaten - Schwimmer'!O$4:O$99,'Stammdaten - Sponsoren'!A6,'Stammdaten - Schwimmer'!F$4:F$99)+SUMIF('Stammdaten - Schwimmer'!S$4:S$99,'Stammdaten - Sponsoren'!A6,'Stammdaten - Schwimmer'!F$4:F$99) -> 1266 | F6: 0.5 | G6: =E6*F6 -> 633 | H6: =IF(D6>0,E6/D6,) -> 63.3 | I6: 2 | J6: 5 | K6: 6 | L6: 9 | M6: 13 | N6: 14 | O6: 15 | P6: 16 | Q6: 17 | R6: 18 | S6: 23 | T6: 24 | U6: 26 | V6: 47 | W6: 48 | X6: 49 | Y6: 55 | Z6: 56 | AA6: 62 | AB6: 65 | AC6: 101 | AD6: 101 | AE6: 101 | AF6: 101 | AG6: 101 | AH6: 101 | AI6: 101 | AJ6: 101 | AK6: 101 | AL6: 101 | AM6: 101 | AN6: 101 | AO6: 101 | AP6: 101
A7: 504 | B7: Schildkröten | C7: Symmetree GmbH | D7: =COUNTIFS(I7:AQ7,">0",I7:AQ7,"<101") -> 6 | E7: =SUMIF('Stammdaten - Schwimmer'!G$4:G$99,'Stammdaten - Sponsoren'!A7,'Stammdaten - Schwimmer'!F$4:F$99)+SUMIF('Stammdaten - Schwimmer'!K$4:K$99,'Stammdaten - Sponsoren'!A7,'Stammdaten - Schwimmer'!F$4:F$99)+SUMIF('Stammdaten - Schwimmer'!O$4:O$99,'Stammdaten - Sponsoren'!A7,'Stammdaten - Schwimmer'!F$4:F$99)+SUMIF('Stammdaten - Schwimmer'!S$4:S$99,'Stammdaten - Sponsoren'!A7,'Stammdaten - Schwimmer'!F$4:F$99)+SUMIF('Stammdaten - Schwimmer'!W$4:W$99,'Stammdaten - Sponsoren'!A7,'Stammdaten - Schwimmer'!F$4:F$99) -> 254 | F7: 0.5 | G7: =E7*F7 -> 127 | H7: =IF(D7>0,E7/D7,) -> 42.333333 | I7: 2 | J7: 16 | K7: 17 | L7: 23 | M7: 24 | N7: 65 | O7: 101 | P7: 101 | Q7: 101 | R7: 101 | S7: 101 | T7: 101 | U7: 101 | V7: 101 | W7: 101 | X7: 101 | Y7: 101 | Z7: 101 | AA7: 101 | AB7: 101 | AC7: 101 | AD7: 101 | AE7: 101 | AF7: 101 | AG7: 101 | AH7: 101 | AI7: 101 | AJ7: 101 | AK7: 101 | AL7: 101 | AM7: 101 | AN7: 101 | AO7: 101 | AP7: 101
A8: 505 | B8: Kanu Klub | C8: Michael Fischer | D8: =COUNTIFS(I8:AQ8,">0",I8:AQ8,"<101") -> 3 | E8: =SUMIF('Stammdaten - Schwimmer'!G$4:G$99,'Stammdaten - Sponsoren'!A8,'Stammdaten - Schwimmer'!F$4:F$99)+SUMIF('Stammdaten - Schwimmer'!K$4:K$99,'Stammdaten - Sponsoren'!A8,'Stammdaten - Schwimmer'!F$4:F$99)+SUMIF('Stammdaten - Schwimmer'!O$4:O$99,'Stammdaten - Sponsoren'!A8,'Stammdaten - Schwimmer'!F$4:F$99)+SUMIF('Stammdaten - Schwimmer'!S$4:S$99,'Stammdaten - Sponsoren'!A8,'Stammdaten - Schwimmer'!F$4:F$99)+SUMIF('Stammdaten - Schwimmer'!W$4:W$99,'Stammdaten - Sponsoren'!A7,'Stammdaten - Schwimmer'!F$4:F$99) -> 159 | F8: 0.5 | G8: =E8*F8 -> 79.5 | H8: =IF(D8>0,E8/D8,) -> 53 | I8: 4 | J8: 5 | K8: 12 | L8: 101 | M8: 101 | N8: 101 | O8: 101 | P8: 101 | Q8: 101 | R8: 101 | S8: 101 | T8: 101 | U8: 101 | V8: 101 | W8: 101 | X8: 101 | Y8: 101 | Z8: 101 | AA8: 101 | AB8: 101 | AC8: 101 | AD8: 101 | AE8: 101 | AF8: 101 | AG8: 101 | AH8: 101 | AI8: 101 | AJ8: 101 | AK8: 101 | AL8: 101 | AM8: 101 | AN8: 101 | AO8: 101 | AP8: 101
A9: 506 | B9: DRK Ortsverein VAI | C9: Eliase Flohr | D9: =COUNTIFS(I9:AQ9,">0",I9:AQ9,"<101") -> 0 | E9: =INDIRECT("'Stammdaten - Schwimmer'!F"&(I9+3))+INDIRECT("'Stammdaten - Schwimmer'!F"&(J9+3))+INDIRECT("'Stammdaten - Schwimmer'!F"&(K9+3))+INDIRECT("'Stammdaten - Schwimmer'!F"&(L9+3))+INDIRECT("'Stammdaten - Schwimmer'!F"&(M9+3))+INDIRECT("'Stammdaten - Schwimmer'!F"&(N9+3))+INDIRECT("'Stammdaten - Schwimmer'!F"&O9+3)+INDIRECT("'Stammdaten - Schwimmer'!F"&(P9+3))+INDIRECT("'Stammdaten - Schwimmer'!F"&(Q9+3))+INDIRECT("'Stammdaten - Schwimmer'!F"&(R9+3))+INDIRECT("'Stammdaten - Schwimmer'!F"&(S9+3))+INDIRECT("'Stammdaten - Schwimmer'!F"&(T9+3))+INDIRECT("'Stammdaten - Schwimmer'!F"&(U9+3))+INDIRECT("'Stammdaten - Schwimmer'!F"&(V9+3))+INDIRECT("'Stammdaten - Schwimmer'!F"&(W9+3))+INDIRECT("'Stammdaten - Schwimmer'!F"&(X9+3))+INDIRECT("'Stammdaten - Schwimmer'!F"&(Y9+3))+INDIRECT("'Stammdaten - Schwimmer'!F"&(Z9+3))+INDIRECT("'Stammdaten - Schwimmer'!F"&(AA9+3))+INDIRECT("'Stammdaten - Schwimmer'!F"&(AB9+3))+INDIRECT("'Stammdaten - Schwimmer'!F"&(AC9+3))+INDIRECT("'Stammdaten - Schwimmer'!F"&(AD9+3))+INDIRECT("'Stammdaten - Schwimmer'!F"&(AE9+3))+INDIRECT("'Stammdaten - Schwimmer'!F"&(AF9+3))+INDIRECT("'Stammdaten - Schwimmer'!F"&(AG9+3)) -> 0 | G9: =E9*F9 -> 0 | H9: =IF(D9>0,E9/D9,) -> 0 | I9: 101 | J9: 101 | K9: 101 | L9: 101 | M9: 101 | N9: 101 | O9: 101 | P9: 101 | Q9: 101 | R9: 101 | S9: 101 | T9: 101 | U9: 101 | V9: 101 | W9: 101 | X9: 101 | Y9: 101 | Z9: 101 | AA9: 101 | AB9: 101 | AC9: 101 | AD9: 101 | AE9: 101 | AF9: 101 | AG9: 101 | AH9: 101 | AI9: 101 | AJ9: 101 | AK9: 101 | AL9: 101 | AM9: 101 | AN9: 101
A10: 507 | B10: Die Hydrotherapeuten | C10: Warner, Chris | D10: =COUNTIFS(I10:AQ10,">0",I10:AQ10,"<101") -> 0 | E10: =INDIRECT("'Stammdaten - Schwimmer'!F"&(I10+3))+INDIRECT("'Stammdaten - Schwimmer'!F"&(J10+3))+INDIRECT("'Stammdaten - Schwimmer'!F"&(K10+3))+INDIRECT("'Stammdaten - Schwimmer'!F"&(L10+3))+INDIRECT("'Stammdaten - Schwimmer'!F"&(M10+3))+INDIRECT("'Stammdaten - Schwimmer'!F"&(N10+3))+INDIRECT("'Stammdaten - Schwimmer'!F"&O10+3)+INDIRECT("'Stammdaten - Schwimmer'!F"&(P10+3))+INDIRECT("'Stammdaten - Schwimmer'!F"&(Q10+3))+INDIRECT("'Stammdaten - Schwimmer'!F"&(R10+3))+INDIRECT("'Stammdaten - Schwimmer'!F"&(S10+3))+INDIRECT("'Stammdaten - Schwimmer'!F"&(T10+3))+INDIRECT("'Stammdaten - Schwimmer'!F"&(U10+3))+INDIRECT("'Stammdaten - Schwimmer'!F"&(V10+3))+INDIRECT("'Stammdaten - Schwimmer'!F"&(W10+3))+INDIRECT("'Stammdaten - Schwimmer'!F"&(X10+3))+INDIRECT("'Stammdaten - Schwimmer'!F"&(Y10+3))+INDIRECT("'Stammdaten - Schwimmer'!F"&(Z10+3))+INDIRECT("'Stammdaten - Schwimmer'!F"&(AA10+3))+INDIRECT("'Stammdaten - Schwimmer'!F"&(AB10+3))+INDIRECT("'Stammdaten - Schwimmer'!F"&(AC10+3))+INDIRECT("'Stammdaten - Schwimmer'!F"&(AD10+3))+INDIRECT("'Stammdaten - Schwimmer'!F"&(AE10+3))+INDIRECT("'Stammdaten - Schwimmer'!F"&(AF10+3))+INDIRECT("'Stammdaten - Schwimmer'!F"&(AG10+3)) -> 0 | G10: =E10*F10 -> 0 | H10: =IF(D10>0,E10/D10,) -> 0 | I10: 101 | J10: 101 | K10: 101 | L10: 101 | M10: 101 | N10: 101 | O10: 101 | P10: 101 | Q10: 101 | R10: 101 | S10: 101 | T10: 101 | U10: 101 | V10: 101 | W10: 101 | X10: 101 | Y10: 101 | Z10: 101 | AA10: 101 | AB10: 101 | AC10: 101 | AD10: 101 | AE10: 101 | AF10: 101 | AG10: 101 | AH10: 101 | AI10: 101 | AJ10: 101 | AK10: 101 | AL10: 101 | AM10: 101 | AN10: 101
A11: 508 | D11: =COUNTIFS(I11:AQ11,">0",I11:AQ11,"<101") -> 0 | E11: =INDIRECT("'Stammdaten - Schwimmer'!F"&(I11+3))+INDIRECT("'Stammdaten - Schwimmer'!F"&(J11+3))+INDIRECT("'Stammdaten - Schwimmer'!F"&(K11+3))+INDIRECT("'Stammdaten - Schwimmer'!F"&(L11+3))+INDIRECT("'Stammdaten - Schwimmer'!F"&(M11+3))+INDIRECT("'Stammdaten - Schwimmer'!F"&(N11+3))+INDIRECT("'Stammdaten - Schwimmer'!F"&O11+3)+INDIRECT("'Stammdaten - Schwimmer'!F"&(P11+3))+INDIRECT("'Stammdaten - Schwimmer'!F"&(Q11+3))+INDIRECT("'Stammdaten - Schwimmer'!F"&(R11+3))+INDIRECT("'Stammdaten - Schwimmer'!F"&(S11+3))+INDIRECT("'Stammdaten - Schwimmer'!F"&(T11+3))+INDIRECT("'Stammdaten - Schwimmer'!F"&(U11+3))+INDIRECT("'Stammdaten - Schwimmer'!F"&(V11+3))+INDIRECT("'Stammdaten - Schwimmer'!F"&(W11+3))+INDIRECT("'Stammdaten - Schwimmer'!F"&(X11+3))+INDIRECT("'Stammdaten - Schwimmer'!F"&(Y11+3))+INDIRECT("'Stammdaten - Schwimmer'!F"&(Z11+3))+INDIRECT("'Stammdaten - Schwimmer'!F"&(AA11+3))+INDIRECT("'Stammdaten - Schwimmer'!F"&(AB11+3))+INDIRECT("'Stammdaten - Schwimmer'!F"&(AC11+3))+INDIRECT("'Stammdaten - Schwimmer'!F"&(AD11+3))+INDIRECT("'Stammdaten - Schwimmer'!F"&(AE11+3))+INDIRECT("'Stammdaten - Schwimmer'!F"&(AF11+3))+INDIRECT("'Stammdaten - Schwimmer'!F"&(AG11+3)) -> 0 | G11: =E11*F11 -> 0 | H11: =IF(D11>0,E11/D11,) -> 0 | I11: 101 | J11: 101 | K11: 101 | L11: 101 | M11: 101 | N11: 101 | O11: 101 | P11: 101 | Q11: 101 | R11: 101 | S11: 101 | T11: 101 | U11: 101 | V11: 101 | W11: 101 | X11: 101 | Y11: 101 | Z11: 101 | AA11: 101 | AB11: 101 | AC11: 101 | AD11: 101 | AE11: 101 | AF11: 101 | AG11: 101 | AH11: 101 | AI11: 101 | AJ11: 101 | AK11: 101 | AL11: 101 | AM11: 101 | AN11: 101
A12: 509 | D12: =COUNTIFS(I12:AQ12,">0",I12:AQ12,"<101") -> 0 | E12: =INDIRECT("'Stammdaten - Schwimmer'!F"&(I12+3))+INDIRECT("'Stammdaten - Schwimmer'!F"&(J12+3))+INDIRECT("'Stammdaten - Schwimmer'!F"&(K12+3))+INDIRECT("'Stammdaten - Schwimmer'!F"&(L12+3))+INDIRECT("'Stammdaten - Schwimmer'!F"&(M12+3))+INDIRECT("'Stammdaten - Schwimmer'!F"&(N12+3))+INDIRECT("'Stammdaten - Schwimmer'!F"&O12+3)+INDIRECT("'Stammdaten - Schwimmer'!F"&(P12+3))+INDIRECT("'Stammdaten - Schwimmer'!F"&(Q12+3))+INDIRECT("'Stammdaten - Schwimmer'!F"&(R12+3))+INDIRECT("'Stammdaten - Schwimmer'!F"&(S12+3))+INDIRECT("'Stammdaten - Schwimmer'!F"&(T12+3))+INDIRECT("'Stammdaten - Schwimmer'!F"&(U12+3))+INDIRECT("'Stammdaten - Schwimmer'!F"&(V12+3))+INDIRECT("'Stammdaten - Schwimmer'!F"&(W12+3))+INDIRECT("'Stammdaten - Schwimmer'!F"&(X12+3))+INDIRECT("'Stammdaten - Schwimmer'!F"&(Y12+3))+INDIRECT("'Stammdaten - Schwimmer'!F"&(Z12+3))+INDIRECT("'Stammdaten - Schwimmer'!F"&(AA12+3))+INDIRECT("'Stammdaten - Schwimmer'!F"&(AB12+3))+INDIRECT("'Stammdaten - Schwimmer'!F"&(AC12+3))+INDIRECT("'Stammdaten - Schwimmer'!F"&(AD12+3))+INDIRECT("'Stammdaten - Schwimmer'!F"&(AE12+3))+INDIRECT("'Stammdaten - Schwimmer'!F"&(AF12+3))+INDIRECT("'Stammdaten - Schwimmer'!F"&(AG12+3)) -> 0 | G12: =E12*F12 -> 0 | H12: =IF(D12>0,E12/D12,) -> 0 | I12: 101 | J12: 101 | K12: 101 | L12: 101 | M12: 101 | N12: 101 | O12: 101 | P12: 101 | Q12: 101 | R12: 101 | S12: 101 | T12: 101 | U12: 101 | V12: 101 | W12: 101 | X12: 101 | Y12: 101 | Z12: 101 | AA12: 101 | AB12: 101 | AC12: 101 | AD12: 101 | AE12: 101 | AF12: 101 | AG12: 101 | AH12: 101 | AI12: 101 | AJ12: 101 | AK12: 101 | AL12: 101 | AM12: 101 | AN12: 101
A13: 510 | D13: =COUNTIFS(I13:AQ13,">0",I13:AQ13,"<101") -> 0 | E13: =INDIRECT("'Stammdaten - Schwimmer'!F"&(I13+3))+INDIRECT("'Stammdaten - Schwimmer'!F"&(J13+3))+INDIRECT("'Stammdaten - Schwimmer'!F"&(K13+3))+INDIRECT("'Stammdaten - Schwimmer'!F"&(L13+3))+INDIRECT("'Stammdaten - Schwimmer'!F"&(M13+3))+INDIRECT("'Stammdaten - Schwimmer'!F"&(N13+3))+INDIRECT("'Stammdaten - Schwimmer'!F"&O13+3)+INDIRECT("'Stammdaten - Schwimmer'!F"&(P13+3))+INDIRECT("'Stammdaten - Schwimmer'!F"&(Q13+3))+INDIRECT("'Stammdaten - Schwimmer'!F"&(R13+3))+INDIRECT("'Stammdaten - Schwimmer'!F"&(S13+3))+INDIRECT("'Stammdaten - Schwimmer'!F"&(T13+3))+INDIRECT("'Stammdaten - Schwimmer'!F"&(U13+3))+INDIRECT("'Stammdaten - Schwimmer'!F"&(V13+3))+INDIRECT("'Stammdaten - Schwimmer'!F"&(W13+3))+INDIRECT("'Stammdaten - Schwimmer'!F"&(X13+3))+INDIRECT("'Stammdaten - Schwimmer'!F"&(Y13+3))+INDIRECT("'Stammdaten - Schwimmer'!F"&(Z13+3))+INDIRECT("'Stammdaten - Schwimmer'!F"&(AA13+3))+INDIRECT("'Stammdaten - Schwimmer'!F"&(AB13+3))+INDIRECT("'Stammdaten - Schwimmer'!F"&(AC13+3))+INDIRECT("'Stammdaten - Schwimmer'!F"&(AD13+3))+INDIRECT("'Stammdaten - Schwimmer'!F"&(AE13+3))+INDIRECT("'Stammdaten - Schwimmer'!F"&(AF13+3))+INDIRECT("'Stammdaten - Schwimmer'!F"&(AG13+3)) -> 0 | G13: =E13*F13 -> 0 | H13: =IF(D13>0,E13/D13,) -> 0 | I13: 101 | J13: 101 | K13: 101 | L13: 101 | M13: 101 | N13: 101 | O13: 101 | P13: 101 | Q13: 101 | R13: 101 | S13: 101 | T13: 101 | U13: 101 | V13: 101 | W13: 101 | X13: 101 | Y13: 101 | Z13: 101 | AA13: 101 | AB13: 101 | AC13: 101 | AD13: 101 | AE13: 101 | AF13: 101 | AG13: 101 | AH13: 101 | AI13: 101 | AJ13: 101 | AK13: 101 | AL13: 101 | AM13: 101 | AN13: 101
A14: 511 | D14: =COUNTIFS(I14:AQ14,">0",I14:AQ14,"<101") -> 0 | E14: =INDIRECT("'Stammdaten - Schwimmer'!F"&(I14+3))+INDIRECT("'Stammdaten - Schwimmer'!F"&(J14+3))+INDIRECT("'Stammdaten - Schwimmer'!F"&(K14+3))+INDIRECT("'Stammdaten - Schwimmer'!F"&(L14+3))+INDIRECT("'Stammdaten - Schwimmer'!F"&(M14+3))+INDIRECT("'Stammdaten - Schwimmer'!F"&(N14+3))+INDIRECT("'Stammdaten - Schwimmer'!F"&O14+3)+INDIRECT("'Stammdaten - Schwimmer'!F"&(P14+3))+INDIRECT("'Stammdaten - Schwimmer'!F"&(Q14+3))+INDIRECT("'Stammdaten - Schwimmer'!F"&(R14+3))+INDIRECT("'Stammdaten - Schwimmer'!F"&(S14+3))+INDIRECT("'Stammdaten - Schwimmer'!F"&(T14+3))+INDIRECT("'Stammdaten - Schwimmer'!F"&(U14+3))+INDIRECT("'Stammdaten - Schwimmer'!F"&(V14+3))+INDIRECT("'Stammdaten - Schwimmer'!F"&(W14+3))+INDIRECT("'Stammdaten - Schwimmer'!F"&(X14+3))+INDIRECT("'Stammdaten - Schwimmer'!F"&(Y14+3))+INDIRECT("'Stammdaten - Schwimmer'!F"&(Z14+3))+INDIRECT("'Stammdaten - Schwimmer'!F"&(AA14+3))+INDIRECT("'Stammdaten - Schwimmer'!F"&(AB14+3))+INDIRECT("'Stammdaten - Schwimmer'!F"&(AC14+3))+INDIRECT("'Stammdaten - Schwimmer'!F"&(AD14+3))+INDIRECT("'Stammdaten - Schwimmer'!F"&(AE14+3))+INDIRECT("'Stammdaten - Schwimmer'!F"&(AF14+3))+INDIRECT("'Stammdaten - Schwimmer'!F"&(AG14+3)) -> 0 | G14: =E14*F14 -> 0 | H14: =IF(D14>0,E14/D14,) -> 0 | I14: 101 | J14: 101 | K14: 101 | L14: 101 | M14: 101 | N14: 101 | O14: 101 | P14: 101 | Q14: 101 | R14: 101 | S14: 101 | T14: 101 | U14: 101 | V14: 101 | W14: 101 | X14: 101 | Y14: 101 | Z14: 101 | AA14: 101 | AB14: 101 | AC14: 101 | AD14: 101 | AE14: 101 | AF14: 101 | AG14: 101 | AH14: 101 | AI14: 101 | AJ14: 101 | AK14: 101 | AL14: 101 | AM14: 101 | AN14: 101
A15: 512 | D15: =COUNTIFS(I15:AQ15,">0",I15:AQ15,"<101") -> 0 | E15: =INDIRECT("'Stammdaten - Schwimmer'!F"&(I15+3))+INDIRECT("'Stammdaten - Schwimmer'!F"&(J15+3))+INDIRECT("'Stammdaten - Schwimmer'!F"&(K15+3))+INDIRECT("'Stammdaten - Schwimmer'!F"&(L15+3))+INDIRECT("'Stammdaten - Schwimmer'!F"&(M15+3))+INDIRECT("'Stammdaten - Schwimmer'!F"&(N15+3))+INDIRECT("'Stammdaten - Schwimmer'!F"&O15+3)+INDIRECT("'Stammdaten - Schwimmer'!F"&(P15+3))+INDIRECT("'Stammdaten - Schwimmer'!F"&(Q15+3))+INDIRECT("'Stammdaten - Schwimmer'!F"&(R15+3))+INDIRECT("'Stammdaten - Schwimmer'!F"&(S15+3))+INDIRECT("'Stammdaten - Schwimmer'!F"&(T15+3))+INDIRECT("'Stammdaten - Schwimmer'!F"&(U15+3))+INDIRECT("'Stammdaten - Schwimmer'!F"&(V15+3))+INDIRECT("'Stammdaten - Schwimmer'!F"&(W15+3))+INDIRECT("'Stammdaten - Schwimmer'!F"&(X15+3))+INDIRECT("'Stammdaten - Schwimmer'!F"&(Y15+3))+INDIRECT("'Stammdaten - Schwimmer'!F"&(Z15+3))+INDIRECT("'Stammdaten - Schwimmer'!F"&(AA15+3))+INDIRECT("'Stammdaten - Schwimmer'!F"&(AB15+3))+INDIRECT("'Stammdaten - Schwimmer'!F"&(AC15+3))+INDIRECT("'Stammdaten - Schwimmer'!F"&(AD15+3))+INDIRECT("'Stammdaten - Schwimmer'!F"&(AE15+3))+INDIRECT("'Stammdaten - Schwimmer'!F"&(AF15+3))+INDIRECT("'Stammdaten - Schwimmer'!F"&(AG15+3)) -> 0 | G15: =E15*F15 -> 0 | H15: =IF(D15>0,E15/D15,) -> 0 | I15: 101 | J15: 101 | K15: 101 | L15: 101 | M15: 101 | N15: 101 | O15: 101 | P15: 101 | Q15: 101 | R15: 101 | S15: 101 | T15: 101 | U15: 101 | V15: 101 | W15: 101 | X15: 101 | Y15: 101 | Z15: 101 | AA15: 101 | AB15: 101 | AC15: 101 | AD15: 101 | AE15: 101 | AF15: 101 | AG15: 101 | AH15: 101 | AI15: 101 | AJ15: 101 | AK15: 101 | AL15: 101 | AM15: 101 | AN15: 101
A16: 513 | D16: =COUNTIFS(I16:AQ16,">0",I16:AQ16,"<101") -> 0 | E16: =INDIRECT("'Stammdaten - Schwimmer'!F"&(I16+3))+INDIRECT("'Stammdaten - Schwimmer'!F"&(J16+3))+INDIRECT("'Stammdaten - Schwimmer'!F"&(K16+3))+INDIRECT("'Stammdaten - Schwimmer'!F"&(L16+3))+INDIRECT("'Stammdaten - Schwimmer'!F"&(M16+3))+INDIRECT("'Stammdaten - Schwimmer'!F"&(N16+3))+INDIRECT("'Stammdaten - Schwimmer'!F"&O16+3)+INDIRECT("'Stammdaten - Schwimmer'!F"&(P16+3))+INDIRECT("'Stammdaten - Schwimmer'!F"&(Q16+3))+INDIRECT("'Stammdaten - Schwimmer'!F"&(R16+3))+INDIRECT("'Stammdaten - Schwimmer'!F"&(S16+3))+INDIRECT("'Stammdaten - Schwimmer'!F"&(T16+3))+INDIRECT("'Stammdaten - Schwimmer'!F"&(U16+3))+INDIRECT("'Stammdaten - Schwimmer'!F"&(V16+3))+INDIRECT("'Stammdaten - Schwimmer'!F"&(W16+3))+INDIRECT("'Stammdaten - Schwimmer'!F"&(X16+3))+INDIRECT("'Stammdaten - Schwimmer'!F"&(Y16+3))+INDIRECT("'Stammdaten - Schwimmer'!F"&(Z16+3))+INDIRECT("'Stammdaten - Schwimmer'!F"&(AA16+3))+INDIRECT("'Stammdaten - Schwimmer'!F"&(AB16+3))+INDIRECT("'Stammdaten - Schwimmer'!F"&(AC16+3))+INDIRECT("'Stammdaten - Schwimmer'!F"&(AD16+3))+INDIRECT("'Stammdaten - Schwimmer'!F"&(AE16+3))+INDIRECT("'Stammdaten - Schwimmer'!F"&(AF16+3))+INDIRECT("'Stammdaten - Schwimmer'!F"&(AG16+3)) -> 0 | G16: =E16*F16 -> 0 | H16: =IF(D16>0,E16/D16,) -> 0 | I16: 101 | J16: 101 | K16: 101 | L16: 101 | M16: 101 | N16: 101 | O16: 101 | P16: 101 | Q16: 101 | R16: 101 | S16: 101 | T16: 101 | U16: 101 | V16: 101 | W16: 101 | X16: 101 | Y16: 101 | Z16: 101 | AA16: 101 | AB16: 101 | AC16: 101 | AD16: 101 | AE16: 101 | AF16: 101 | AG16: 101 | AH16: 101 | AI16: 101 | AJ16: 101 | AK16: 101 | AL16: 101 | AM16: 101 | AN16: 101
